Workbook
Name GradeTable: #REF!
Name RowTitleRegion1..U6: #REF!
Name RowTitleRegion2..X9: #REF!
Name RowTitleRegion3..H12: #REF!
Name Title1: #REF!
Name TitleRegion1..G24.1: #REF!
Name TotalPoints: #REF!

Sheet Events & Leaderboard
B2: 2025 DE World Tour Leaderboard
B3: Name | C3: Net | D3: 3+ | E3: Team | F3: Par 3 | G3: Par 5 | H3: Total | I3: Points behind lead | J3: 3 putts | K3: 💩
B4: Dave | C4: =SUM('Jan - Magenta:Dec - TBC'!Z17) -> 120 | D4: =SUM('Jan - Magenta:Dec - TBC'!AA17) -> 33 | E4: =SUM('Jan - Magenta:Dec - TBC'!AB17) -> 10 | F4: =SUM('Jan - Magenta:Dec - TBC'!AC17) -> 0 | G4: =SUM('Jan - Magenta:Dec - TBC'!AD17) -> 0 | H4: =SUM(C4:G4) -> 163 | I4: =MAX($H$4:$H$7)-H4 -> 47 | J4: =SUM('Jan - Magenta:Dec - TBC'!AF16) -> 12 | K4: =COUNTIF($L$11:$L$22,B4) -> 0
B5: Scott | C5: =SUM('Jan - Magenta:Dec - TBC'!Z15) -> 110 | D5: =SUM('Jan - Magenta:Dec - TBC'!AA15) -> 44 | E5: =SUM('Jan - Magenta:Dec - TBC'!AB15) -> 0 | F5: =SUM('Jan - Magenta:Dec - TBC'!AC15) -> 0 | G5: =SUM('Jan - Magenta:Dec - TBC'!AD15) -> 0 | H5: =SUM(C5:G5) -> 154 | I5: =MAX($H$4:$H$7)-H5 -> 56 | J5: =SUM('Jan - Magenta:Dec - TBC'!AF14) -> 5 | K5: =COUNTIF($L$11:$L$22,B5) -> 1
B6: Mitch | C6: =SUM('Jan - Magenta:Dec - TBC'!Z11) -> 100 | D6: =SUM('Jan - Magenta:Dec - TBC'!AA11) -> 18 | E6: =SUM('Jan - Magenta:Dec - TBC'!AB11) -> 30 | F6: =SUM('Jan - Magenta:Dec - TBC'!AC11) -> 5 | G6: =SUM('Jan - Magenta:Dec - TBC'!AD11) -> 5 | H6: =SUM(C6:G6) -> 158 | I6: =MAX($H$4:$H$7)-H6 -> 52 | J6: =SUM('Jan - Magenta:Dec - TBC'!AF10) -> 10 | K6: =COUNTIF($L$11:$L$22,B6) -> 2
B7: Colby | C7: =SUM('Jan - Magenta:Dec - TBC'!Z13) -> 140 | D7: =SUM('Jan - Magenta:Dec - TBC'!AA13) -> 35 | E7: =SUM('Jan - Magenta:Dec - TBC'!AB13) -> 20 | F7: =SUM('Jan - Magenta:Dec - TBC'!AC13) -> 5 | G7: =SUM('Jan - Magenta:Dec - TBC'!AD13) -> 10 | H7: =SUM(C7:G7) -> 210 | I7: =MAX($H$4:$H$7)-H7 -> 0 | J7: =SUM('Jan - Magenta:Dec - TBC'!AF12) -> 8 | K7: =COUNTIF($L$11:$L$22,B7) -> 0
B9: 2025 DE World Tour Event Schedule | K9: Shit Trophy winner | N9: Net Score | O9: Points
B10: Date | C10: Course | D10: Teams | E10: Team Event | F10: Mitch Points | G10: Colby Points | H10: Scott Points | I10: Dave Points | K10: Date | L10: Name | N10: <70 | O10: 70
B11: January | C11: Magenta | D11: MT-DB, SP-CG | E11: Multiplier | F11: ='Jan - Magenta'!$AE$11 -> 62 | G11: ='Jan - Magenta'!$AE$13 -> 57 | H11: ='Jan - Magenta'!$AE$15 -> 63 | I11: ='Jan - Magenta'!$AE$17 -> 78 | K11: January | L11: Mitch | N11: 71-75 | O11: 50
B12: February | C12: Toronto | D12: DB-SP, MT-CG | E12: Worst Ball | F12: ='Feb - Toronto'!$AE$11 -> 45 | G12: ='Feb - Toronto'!$AE$13 -> 76 | H12: ='Feb - Toronto'!$AE$15 -> 55 | I12: ='Feb - Toronto'!$AE$17 -> 55 | K12: February | L12: Mitch | N12: 76-80 | O12: 40
B13: March | C13: Shortland | D13: DB-SP, MT-CG | E13: Multiplier | F13: ='Mar - Shortland'!$AE$11 -> 51 | G13: ='Mar - Shortland'!$AE$13 -> 77 | H13: ='Mar - Shortland'!$AE$15 -> 36 | I13: ='Mar - Shortland'!$AE$17 -> 30 | K13: March | L13: Scott | N13: 81-85 | O13: 35
B14: April | F14: ='Apr - Waratah'!$AE$11 -> 0 | G14: ='Apr - Waratah'!$AE$13 -> 0 | H14: ='Apr - Waratah'!$AE$15 -> 0 | I14: ='Apr - Waratah'!$AE$17 -> 0 | K14: April | L14: 0 | N14: 86-90 | O14: 30
B15: May | F15: ='May - TBC'!$AE$11 -> 0 | G15: ='May - TBC'!$AE$13 -> 0 | H15: ='May - TBC'!$AE$15 -> 0 | I15: ='May - TBC'!$AE$17 -> 0 | K15: May | L15: 0 | N15: 91-100+ | O15: 25
B16: June | F16: ='Jun - TBC'!$AE$11 -> 0 | G16: ='Jun - TBC'!$AE$13 -> 0 | H16: ='Jun - TBC'!$AE$15 -> 0 | I16: ='Jun - TBC'!$AE$17 -> 0 | K16: June | L16: 0 | N16: 3+ points | O16: equal value
B17: July | F17: ='July - TBC'!$AE$11 -> 0 | G17: ='July - TBC'!$AE$13 -> 0 | H17: ='July - TBC'!$AE$15 -> 0 | I17: ='July - TBC'!$AE$17 -> 0 | K17: July | L17: 0 | N17: Par 3's | O17: 5
B18: August | F18: ='August - TBC'!$AE$11 -> 0 | G18: ='August - TBC'!$AE$13 -> 0 | H18: ='August - TBC'!$AE$15 -> 0 | I18: ='August - TBC'!$AE$17 -> 0 | K18: August | L18: 0 | N18: Par 5's | O18: 5
B19: September | F19: ='Sept - TBC'!$AE$11 -> 0 | G19: ='Sept - TBC'!$AE$13 -> 0 | H19: ='Sept - TBC'!$AE$15 -> 0 | I19: ='Sept - TBC'!$AE$17 -> 0 | K19: September | L19: 0 | N19: Team | O19: 10
B20: October | F20: ='Oct - TBC'!$AE$11 -> 0 | G20: ='Oct - TBC'!$AE$13 -> 0 | H20: ='Oct - TBC'!$AE$15 -> 0 | I20: ='Oct - TBC'!$AE$17 -> 0 | K20: October | L20: -
B21: November | F21: ='Nov - TBC'!$AE$11 -> 0 | G21: ='Nov - TBC'!$AE$13 -> 0 | H21: ='Nov - TBC'!$AE$15 -> 0 | I21: ='Nov - TBC'!$AE$17 -> 0 | K21: November | L21: -
B22: December | F22: ='Dec - TBC'!$AE$11 -> 0 | G22: ='Dec - TBC'!$AE$13 -> 0 | H22: ='Dec - TBC'!$AE$15 -> 0 | I22: ='Dec - TBC'!$AE$17 -> 0 | K22: December | L22: -
Q23: Cumulative scores
B24: 2025 DE Handicap Trend | Q24: Mitch Points | R24: Colby Points | S24: Scott Points | T24: Dave Points
B25: Date | C25: Course | D25: Mitch | E25: Colby | F25: Scott | G25: Dave | Q25: =F11 -> 62 | R25: =G11 -> 57 | S25: =H11 -> 63 | T25: =I11 -> 78
B26: January | C26: Magenta | D26: 13.194 | E26: 17.101 | F26: 21.513 | G26: 15.326 | Q26: =Q25+F12 -> 107 | R26: =R25+G12 -> 133 | S26: =S25+H12 -> 118 | T26: =T25+I12 -> 133
B27: February | C27: Toronto | D27: 13.194 | E27: 17.034 | F27: 21.513 | G27: 15.072 | Q27: =Q26+F13 -> 158 | R27: =R26+G13 -> 210 | S27: =S26+H13 -> 154 | T27: =T26+I13 -> 163
B28: March | C28: Shortland | D28: 13.194 | E28: 16.84 | F28: 21.513 | G28: 15.072 | Q28: =Q27+F14 -> 158 | R28: =R27+G14 -> 210 | S28: =S27+H14 -> 154 | T28: =T27+I14 -> 163
B29: April | C29: Waratah | D29: 13.193612 | E29: 16.673987 | F29: 21.614829 | G29: 15.078312 | Q29: =Q28+F15 -> 158 | R29: =R28+G15 -> 210 | S29: =S28+H15 -> 154 | T29: =T28+I15 -> 163
B30: May | Q30: =Q29+F16 -> 158 | R30: =R29+G16 -> 210 | S30: =S29+H16 -> 154 | T30: =T29+I16 -> 163
B31: June | Q31: =Q30+F17 -> 158 | R31: =R30+G17 -> 210 | S31: =S30+H17 -> 154 | T31: =T30+I17 -> 163
B32: July | Q32: =Q31+F18 -> 158 | R32: =R31+G18 -> 210 | S32: =S31+H18 -> 154 | T32: =T31+I18 -> 163
B33: August | Q33: =Q32+F19 -> 158 | R33: =R32+G19 -> 210 | S33: =S32+H19 -> 154 | T33: =T32+I19 -> 163
B34: September | Q34: =Q33+F20 -> 158 | R34: =R33+G20 -> 210 | S34: =S33+H20 -> 154 | T34: =T33+I20 -> 163
B35: October | Q35: =Q34+F21 -> 158 | R35: =R34+G21 -> 210 | S35: =S34+H21 -> 154 | T35: =T34+I21 -> 163
B36: November | Q36: =Q35+F22 -> 158 | R36: =R35+G22 -> 210 | S36: =S35+H22 -> 154 | T36: =T35+I22 -> 163
B37: December

Sheet Mitch
A1: Handicap --> | B1: =AVERAGE(SMALL(INDIRECT("F3:F22"),1),SMALL(INDIRECT("F3:F22"),2),SMALL(INDIRECT("F3:F22"),3),SMALL(INDIRECT("F3:F22"),4),SMALL(INDIRECT("F3:F22"),5), SMALL(INDIRECT("F3:F22"),6),SMALL(INDIRECT("F3:F22"),7),SMALL(INDIRECT("F3:F22"),8)) -> 13.193612 | C1: AVG20 | D1: =AVERAGE(C3:C22) -> 91.9 | E1: AVG8 | F1: =ROUNDDOWN(AVERAGE(SMALL(INDIRECT("c3:c22"),1),SMALL(INDIRECT("c3:c22"),2),SMALL(INDIRECT("c3:c22"),3),SMALL(INDIRECT("c3:c22"),4),SMALL(INDIRECT("c3:c22"),5), SMALL(INDIRECT("c3:c22"),6),SMALL(INDIRECT("c3:c22"),7),SMALL(INDIRECT("c3:c22"),8)),1) -> 86
A2: Date | B2: Course | C2: Score | D2: Rating | E2: Slope | F2: Differential | I2: Record of older scores
A3: 45671 | B3: Shortland Waters | C3: 88 | D3: 71 | E3: 130 | F3: =(((C3-G3)-D3)*113)/E3 -> 14.776923 | I3: 44986 | J3: Merewether | K3: 96 | L3: 70 | M3: 133 | N3: 22.090226
A4: 45709 | B4: Kooindah Waters | C4: 92 | D4: 72 | E4: 139 | F4: =(((C4-G4)-D4)*113)/E4 -> 16.258993 | I4: 45022 | J4: Gosford | K4: 88 | L4: 69 | M4: 119 | N4: 18.042017
A5: 45730 | B5: Kooindah Waters | C5: 88 | D5: 72 | E5: 139 | F5: =(((C5-G5)-D5)*113)/E5 -> 13.007194 | I5: 45036 | J5: Shortland | K5: 96 | L5: 70 | M5: 130 | N5: 22.6
A6: 45755 | B6: Waratah | C6: 80 | D6: 70 | E6: 129 | F6: =(((C6-G6)-D6)*113)/E6 -> 8.7596899 | I6: 45093 | J6: Shelly Beach | K6: 94 | L6: 70 | M6: 118 | N6: 22.983051
A7: 45792 | B7: Hunter Valley | C7: 96 | D7: 70 | E7: 126 | F7: =(((C7-G7)-D7)*113)/E7 -> 23.31746 | I7: 45141 | J7: Toukley | K7: 96 | L7: 72 | M7: 124 | N7: 21.870968
A8: 45835 | B8: The Springs | C8: 85 | D8: 71 | E8: 127 | F8: =(((C8-G8)-D8)*113)/E8 -> 12.456693 | I8: 45170 | J8: Merewether | K8: 91 | L8: 70 | M8: 133 | N8: 17.842105
A9: 45848 | B9: Magenta | C9: 96 | D9: 72 | E9: 135 | F9: =(((C9-G9)-D9)*113)/E9 -> 20.088889 | I9: 45247 | J9: Wyong | K9: 90 | L9: 69 | M9: 119 | N9: 19.941176
A10: 45897 | B10: Toukley | C10: 95 | D10: 72 | E10: 124 | F10: =(((C10-G10)-D10)*113)/E10 -> 20.959677 | I10: 45281 | J10: Cypress | K10: 84 | L10: 70 | M10: 136 | N10: 11.632353
A11: 45926 | B11: Belmont | C11: 95 | D11: 72 | E11: 125 | F11: =(((C11-G11)-D11)*113)/E11 -> 20.792 | I11: 45321 | J11: Toronto | K11: 85 | L11: 70 | M11: 127 | N11: 13.346457
A12: 46049 | B12: Magenta | C12: 102 | D12: 73 | E12: 135 | F12: =(((C12-G12)-D12)*113)/E12 -> 24.274074 | I12: 45345 | J12: Magenta | K12: 93 | L12: 72 | M12: 135 | N12: 17.577778
A13: 46150 | B13: Toronto | C13: 93 | D13: 69 | E13: 128 | F13: =(((C13-G13)-D13)*113)/E13 -> 21.1875 | I13: 45370 | J13: Hunter Valley | K13: 98 | L13: 70 | M13: 126 | N13: 25.111111
A14: 46174 | B14: Shortland Waters | C14: 96 | D14: 72 | E14: 128 | F14: =(((C14-G14)-D14)*113)/E14 -> 21.1875 | I14: 45400 | J14: Kooindah Waters | K14: 93 | L14: 72 | M14: 139 | N14: 17.071942
... A22: 45631 | B22: Nelson Bay | C22: 103 | D22: 71 | E22: 125 | F22: =(((C22-G22)-D22)*113)/E22 -> 28.928 | I22: 45631 | J22: Nelson Bay | K22: 103 | L22: 71 | M22: 125 | N22: 28.928
A27: Course Rating and Slope Database: | C27: https://golf.com.au/find-a-place-to-play?view=list&filter=venue&sort=distance&latitude=-33.3101078&longitude=151.522855&distance=15

Sheet Colby
A1: Handicap --> | B1: =AVERAGE(SMALL(INDIRECT("F3:F22"),1),SMALL(INDIRECT("F3:F22"),2),SMALL(INDIRECT("F3:F22"),3),SMALL(INDIRECT("F3:F22"),4),SMALL(INDIRECT("F3:F22"),5), SMALL(INDIRECT("F3:F22"),6),SMALL(INDIRECT("F3:F22"),7),SMALL(INDIRECT("F3:F22"),8)) -> 16.673987 | C1: AVG20 | D1: =AVERAGE(C3:C22) -> 95.6 | E1: AVG8 | F1: =ROUNDDOWN(AVERAGE(SMALL(INDIRECT("c3:c22"),1),SMALL(INDIRECT("c3:c22"),2),SMALL(INDIRECT("c3:c22"),3),SMALL(INDIRECT("c3:c22"),4),SMALL(INDIRECT("c3:c22"),5), SMALL(INDIRECT("c3:c22"),6),SMALL(INDIRECT("c3:c22"),7),SMALL(INDIRECT("c3:c22"),8)),1) -> 90.6
A2: Date | B2: Course | C2: Score | D2: Rating | E2: Slope | F2: Differential | I2: Record of older scores
A3: 45671 | B3: Shortland Waters | C3: 95 | D3: 71 | E3: 130 | F3: =(((C3-G3)-D3)*113)/E3 -> 20.861538 | I3: 44986 | J3: Merewether | K3: 101 | L3: 70 | M3: 133 | N3: 26.338346
A4: 45709 | B4: Kooindah Waters | C4: 89 | D4: 72 | E4: 139 | F4: =(((C4-G4)-D4)*113)/E4 -> 13.820144 | I4: 45022 | J4: Gosford | K4: 91 | L4: 69 | M4: 119 | N4: 20.890756
A5: 45730 | B5: Kooindah Waters | C5: 90 | D5: 72 | E5: 139 | F5: =(((C5-G5)-D5)*113)/E5 -> 14.633094 | I5: 45036 | J5: Shortland | K5: 95 | L5: 70 | M5: 130 | N5: 21.730769
A6: 45755 | B6: Waratah | C6: 90 | D6: 70 | E6: 129 | F6: =(((C6-G6)-D6)*113)/E6 -> 17.51938 | I6: 45093 | J6: Shelly Beach | K6: 96 | L6: 70 | M6: 118 | N6: 24.898305
A7: 45792 | B7: Hunter Valley | C7: 93 | D7: 70 | E7: 126 | F7: =(((C7-G7)-D7)*113)/E7 -> 20.626984 | I7: 45141 | J7: Toukley | K7: 105 | L7: 72 | M7: 124 | N7: 30.072581
A8: 45835 | B8: The Springs | C8: 97 | D8: 71 | E8: 127 | F8: =(((C8-G8)-D8)*113)/E8 -> 23.133858 | I8: 45170 | J8: Merewether | K8: 98 | L8: 70 | M8: 133 | N8: 23.789474
A9: 45848 | B9: Magenta | C9: 92 | D9: 72 | E9: 135 | F9: =(((C9-G9)-D9)*113)/E9 -> 16.740741 | I9: 45247 | J9: Wyong | K9: 84 | L9: 69 | M9: 119 | N9: 14.243697
A10: 45897 | B10: Toukley | C10: 98 | D10: 72 | E10: 124 | F10: =(((C10-G10)-D10)*113)/E10 -> 23.693548 | I10: 45281 | J10: Cypress | K10: 102 | L10: 70 | M10: 136 | N10: 26.588235
A11: 45926 | B11: Belmont | C11: 92 | D11: 72 | E11: 125 | F11: =(((C11-G11)-D11)*113)/E11 -> 18.08 | I11: 45321 | J11: Toronto | K11: 83 | L11: 70 | M11: 127 | N11: 11.566929
A12: 46049 | B12: Magenta | C12: 97 | D12: 73 | E12: 135 | F12: =(((C12-G12)-D12)*113)/E12 -> 20.088889 | I12: 45345 | J12: Magenta | K12: 103 | L12: 72 | M12: 135 | N12: 25.948148
A13: 46150 | B13: Toronto | C13: 90 | D13: 69 | E13: 128 | F13: =(((C13-G13)-D13)*113)/E13 -> 18.539062 | I13: 45370 | J13: Hunter Valley | K13: 102 | L13: 70 | M13: 126 | N13: 28.698413
A14: 46174 | B14: Shortland Waters | C14: 92 | D14: 72 | E14: 128 | F14: =(((C14-G14)-D14)*113)/E14 -> 17.65625 | I14: 45400 | J14: Kooindah Waters | K14: 103 | L14: 72 | M14: 139 | N14: 25.201439
... A22: 45631 | B22: Nelson Bay | C22: 92 | D22: 71 | E22: 125 | F22: =(((C22-G22)-D22)*113)/E22 -> 18.984 | I22: 45631 | J22: Nelson Bay | K22: 92 | L22: 71 | M22: 125 | N22: 18.984
A26: Course Rating and Slope Database: | C26: https://golf.com.au/find-a-place-to-play?view=list&filter=venue&sort=distance&latitude=-33.3101078&longitude=151.522855&distance=15

Sheet Scott
A1: Handicap --> | B1: =AVERAGE(SMALL(INDIRECT("F3:F22"),1),SMALL(INDIRECT("F3:F22"),2),SMALL(INDIRECT("F3:F22"),3),SMALL(INDIRECT("F3:F22"),4),SMALL(INDIRECT("F3:F22"),5), SMALL(INDIRECT("F3:F22"),6),SMALL(INDIRECT("F3:F22"),7),SMALL(INDIRECT("F3:F22"),8)) -> 21.614829 | C1: AVG20 | D1: =AVERAGE(C3:C22) -> 100.15 | E1: AVG8 | F1: =ROUNDDOWN(AVERAGE(SMALL(INDIRECT("c3:c22"),1),SMALL(INDIRECT("c3:c22"),2),SMALL(INDIRECT("c3:c22"),3),SMALL(INDIRECT("c3:c22"),4),SMALL(INDIRECT("c3:c22"),5), SMALL(INDIRECT("c3:c22"),6),SMALL(INDIRECT("c3:c22"),7),SMALL(INDIRECT("c3:c22"),8)),1) -> 95.7
A2: Date | B2: Course | C2: Score | D2: Rating | E2: Slope | F2: Differential | I2: Record of older scores
A3: 45671 | B3: Shortland Waters | C3: 96 | D3: 71 | E3: 130 | F3: =(((C3-G3)-D3)*113)/E3 -> 21.730769 | I3: 44986 | J3: Merewether | K3: 102 | L3: 70 | M3: 133 | N3: 27.18797
A4: 45709 | B4: Kooindah Waters | C4: 115 | D4: 72 | E4: 139 | F4: =(((C4-G4)-D4)*113)/E4 -> 34.956835 | I4: 45022 | J4: Gosford | K4: 103 | L4: 69 | M4: 119 | N4: 32.285714
A5: 45730 | B5: Kooindah Waters | C5: 96 | D5: 72 | E5: 139 | F5: =(((C5-G5)-D5)*113)/E5 -> 19.510791 | I5: 45036 | J5: Shortland | K5: 101 | L5: 70 | M5: 130 | N5: 26.946154
A6: 45755 | B6: Waratah | C6: 95 | D6: 70 | E6: 129 | F6: =(((C6-G6)-D6)*113)/E6 -> 21.899225 | I6: 45093 | J6: Shelly Beach | K6: 101 | L6: 70 | M6: 118 | N6: 29.686441
A7: 45792 | B7: Hunter Valley | C7: 97 | D7: 70 | E7: 126 | F7: =(((C7-G7)-D7)*113)/E7 -> 24.214286 | I7: 45141 | J7: Toukley | K7: 96 | L7: 72 | M7: 124 | N7: 21.870968
A8: 45835 | B8: The Springs | C8: 105 | D8: 71 | E8: 127 | F8: =(((C8-G8)-D8)*113)/E8 -> 30.251969 | I8: 45170 | J8: Merewether | K8: 105 | L8: 70 | M8: 133 | N8: 29.736842
A9: 45848 | B9: Magenta | C9: 104 | D9: 72 | E9: 135 | F9: =(((C9-G9)-D9)*113)/E9 -> 26.785185 | I9: 45247 | J9: Wyong | K9: 105 | L9: 69 | M9: 119 | N9: 34.184874
A10: 45897 | B10: Toukley | C10: 99 | D10: 72 | E10: 124 | F10: =(((C10-G10)-D10)*113)/E10 -> 24.604839 | I10: 45281 | J10: Cypress | K10: 98 | L10: 70 | M10: 136 | N10: 23.264706
A11: 45926 | B11: Belmont | C11: 97 | D11: 72 | E11: 125 | F11: =(((C11-G11)-D11)*113)/E11 -> 22.6 | I11: 45321 | J11: Toronto | K11: 85 | L11: 70 | M11: 127 | N11: 13.346457
A12: 46049 | B12: Magenta | C12: 104 | D12: 73 | E12: 135 | F12: =(((C12-G12)-D12)*113)/E12 -> 25.948148 | I12: 45345 | J12: Magenta | K12: 101 | L12: 72 | M12: 135 | N12: 24.274074
A13: 46150 | B13: Toronto | C13: 98 | D13: 69 | E13: 128 | F13: =(((C13-G13)-D13)*113)/E13 -> 25.601562 | I13: 45370 | J13: Hunter Valley | K13: 107 | L13: 70 | M13: 126 | N13: 33.18254
A14: 46174 | B14: Shortland Waters | C14: 110 | D14: 72 | E14: 128 | F14: =(((C14-G14)-D14)*113)/E14 -> 33.546875 | I14: 45400 | J14: Kooindah Waters | K14: 99 | L14: 72 | M14: 139 | N14: 21.94964
... A22: 45631 | B22: Nelson Bay | C22: 94 | D22: 71 | E22: 125 | F22: =(((C22-G22)-D22)*113)/E22 -> 20.792 | I22: 45631 | J22: Nelson Bay | K22: 94 | L22: 71 | M22: 125 | N22: 20.792
B24: Course Rating and Slope Database: | D24: https://golf.com.au/find-a-place-to-play?view=list&filter=venue&sort=distance&latitude=-33.3101078&longitude=151.522855&distance=15

Sheet Dave
A1: Handicap --> | B1: =AVERAGE(SMALL(INDIRECT("F3:F22"),1),SMALL(INDIRECT("F3:F22"),2),SMALL(INDIRECT("F3:F22"),3),SMALL(INDIRECT("F3:F22"),4),SMALL(INDIRECT("F3:F22"),5), SMALL(INDIRECT("F3:F22"),6),SMALL(INDIRECT("F3:F22"),7),SMALL(INDIRECT("F3:F22"),8)) -> 15.078312 | C1: AVG20 | D1: =AVERAGE(C3:C22) -> 92.9 | E1: AVG8 | F1: =ROUNDDOWN(AVERAGE(SMALL(INDIRECT("c3:c22"),1),SMALL(INDIRECT("c3:c22"),2),SMALL(INDIRECT("c3:c22"),3),SMALL(INDIRECT("c3:c22"),4),SMALL(INDIRECT("c3:c22"),5), SMALL(INDIRECT("c3:c22"),6),SMALL(INDIRECT("c3:c22"),7),SMALL(INDIRECT("c3:c22"),8)),1) -> 88.3
A2: Date | B2: Course | C2: Score | D2: Rating | E2: Slope | F2: Differential | I2: Record of older scores
A3: 45671 | B3: Shortland Waters | C3: 86 | D3: 71 | E3: 130 | F3: =(((C3-G3)-D3)*113)/E3 -> 13.038462 | I3: 44986 | J3: Merewether | K3: 102 | L3: 70 | M3: 133 | N3: 27.18797
A4: 45709 | B4: Kooindah Waters | C4: 98 | D4: 72 | E4: 139 | F4: =(((C4-G4)-D4)*113)/E4 -> 21.136691 | I4: 45022 | J4: Gosford | K4: 91 | L4: 69 | M4: 119 | N4: 20.890756
A5: 45730 | B5: Kooindah Waters | C5: 96 | D5: 72 | E5: 139 | F5: =(((C5-G5)-D5)*113)/E5 -> 19.510791 | I5: 45036 | J5: Shortland | K5: 91 | L5: 70 | M5: 130 | N5: 18.253846
A6: 45755 | B6: Waratah | C6: 87 | D6: 70 | E6: 129 | F6: =(((C6-G6)-D6)*113)/E6 -> 14.891473 | I6: 45093 | J6: Shelly Beach | K6: 90 | L6: 70 | M6: 118 | N6: 19.152542
A7: 45792 | B7: Hunter Valley | C7: 90 | D7: 70 | E7: 126 | F7: =(((C7-G7)-D7)*113)/E7 -> 17.936508 | I7: 45141 | J7: Toukley | K7: 96 | L7: 72 | M7: 124 | N7: 21.870968
A8: 45835 | B8: The Springs | C8: 97 | D8: 71 | E8: 127 | F8: =(((C8-G8)-D8)*113)/E8 -> 23.133858 | I8: 45170 | J8: Merewether | K8: 95 | L8: 70 | M8: 133 | N8: 21.240602
A9: 45848 | B9: Magenta | C9: 98 | D9: 72 | E9: 135 | F9: =(((C9-G9)-D9)*113)/E9 -> 21.762963 | I9: 45247 | J9: Wyong | K9: 87 | L9: 69 | M9: 119 | N9: 17.092437
A10: 45897 | B10: Toukley | C10: 96 | D10: 72 | E10: 124 | F10: =(((C10-G10)-D10)*113)/E10 -> 21.870968 | I10: 45281 | J10: Cypress | K10: 84 | L10: 70 | M10: 136 | N10: 11.632353
A11: 45926 | B11: Belmont | C11: 88 | D11: 72 | E11: 125 | F11: =(((C11-G11)-D11)*113)/E11 -> 14.464 | I11: 45321 | J11: Toronto | K11: 92 | L11: 70 | M11: 127 | N11: 19.574803
A12: 46049 | B12: Magenta | C12: 92 | D12: 73 | E12: 135 | F12: =(((C12-G12)-D12)*113)/E12 -> 15.903704 | I12: 45345 | J12: Magenta | K12: 94 | L12: 72 | M12: 135 | N12: 18.414815
A13: 46150 | B13: Toronto | C13: 91 | D13: 69 | E13: 128 | F13: =(((C13-G13)-D13)*113)/E13 -> 19.421875 | I13: 45370 | J13: Hunter Valley | K13: 94 | L13: 70 | M13: 126 | N13: 21.52381
A14: 46174 | B14: Shortland Waters | C14: 103 | D14: 72 | E14: 128 | F14: =(((C14-G14)-D14)*113)/E14 -> 27.367188 | I14: 45400 | J14: Kooindah Waters | K14: 94 | L14: 72 | M14: 139 | N14: 17.884892
... A22: 45631 | B22: Nelson Bay | C22: 87 | D22: 71 | E22: 125 | F22: =(((C22-G22)-D22)*113)/E22 -> 14.464 | I22: 45631 | J22: Nelson Bay | K22: 87 | L22: 71 | M22: 125 | N22: 14.464
A26: Course Rating and Slope Database: | C26: https://golf.com.au/find-a-place-to-play?view=list&filter=venue&sort=distance&latitude=-33.3101078&longitude=151.522855&distance=15

Sheet Jan - Magenta
C4: Golf Course - Magenta Shores
C5: Date: 27/1/2026
C6: Hole | D6: 1 | E6: 2 | F6: 3 | G6: 4 | H6: 5 | I6: 6 | J6: 7 | K6: 8 | L6: 9 | M6: F/Nine | N6: 10 | O6: 11 | P6: 12 | Q6: 13 | R6: 14 | S6: 15 | T6: 16 | U6: 17 | V6: 18 | W6: B/Nine | X6: Total | Y6: S/Pnts | Z6: Net | AA6: 3+ | AB6: Team | AC6: Par 3 | AD6: Par 5 | AE6: Total | AF6: 3 putts
C7: Par | D7: 4 | E7: 5 | F7: 4 | G7: 3 | H7: 4 | I7: 4 | J7: 3 | K7: 5 | L7: 4 | M7: =SUM(D7:L7) -> 36 | N7: 5 | O7: 4 | P7: 3 | Q7: 4 | R7: 4 | S7: 3 | T7: 4 | U7: 4 | V7: 5 | W7: =SUM(N7:V7) -> 36 | X7: =M7+W7 -> 72 | AA7: Points | AB7: Points | AC7: Points | AD7: Points | AE7: Points | AG7: Net Score | AH7: Points
C8: Index | D8: 5 | E8: 9 | F8: 3 | G8: 14 | H8: 11 | I8: 15 | J8: 18 | K8: 13 | L8: 1 | N8: 12 | O8: 10 | P8: 16 | Q8: 8 | R8: 2 | S8: 17 | T8: 6 | U8: 7 | V8: 4 | AG8: <70 | AH8: 70
C9: H/Cap | AG9: 71-75 | AH9: 50
B10: Mitch | C10: 15 | D10: 4 | E10: 6 | F10: 8 | G10: 3 | H10: 5 | I10: 8 | J10: 3 | K10: 5 | L10: 6 | M10: =SUM(D10:L10) -> 48 | N10: 6 | O10: 6 | P10: 3 | Q10: 6 | R10: 6 | S10: 8 | T10: 7 | U10: 4 | V10: 8 | W10: =SUM(N10:V10) -> 54 | X10: =+M10+W10 -> 102 | Y10: =X11 -> 26 | Z10: =X10-C10 -> 87 | AF10: 5 | AG10: 76-80 | AH10: 40
B11: pts | D11: =MAX(0,2+D$7+(D$8<=$C10)+(D$8<=MAX($C10-18,0))+(D$8<=MAX($C10-36,0))-D10)*NOT(ISBLANK($C10)) -> 3 | E11: =MAX(0,2+E$7+(E$8<=$C10)+(E$8<=MAX($C10-18,0))+(E$8<=MAX($C10-36,0))-E10)*NOT(ISBLANK($C10)) -> 2 | F11: =MAX(0,2+F$7+(F$8<=$C10)+(F$8<=MAX($C10-18,0))+(F$8<=MAX($C10-36,0))-F10)*NOT(ISBLANK($C10)) -> 0 | G11: =MAX(0,2+G$7+(G$8<=$C10)+(G$8<=MAX($C10-18,0))+(G$8<=MAX($C10-36,0))-G10)*NOT(ISBLANK($C10)) -> 3 | H11: =MAX(0,2+H$7+(H$8<=$C10)+(H$8<=MAX($C10-18,0))+(H$8<=MAX($C10-36,0))-H10)*NOT(ISBLANK($C10)) -> 2 | I11: =MAX(0,2+I$7+(I$8<=$C10)+(I$8<=MAX($C10-18,0))+(I$8<=MAX($C10-36,0))-I10)*NOT(ISBLANK($C10)) -> 0 | J11: =MAX(0,2+J$7+(J$8<=$C10)+(J$8<=MAX($C10-18,0))+(J$8<=MAX($C10-36,0))-J10)*NOT(ISBLANK($C10)) -> 2 | K11: =MAX(0,2+K$7+(K$8<=$C10)+(K$8<=MAX($C10-18,0))+(K$8<=MAX($C10-36,0))-K10)*NOT(ISBLANK($C10)) -> 3 | L11: =MAX(0,2+L$7+(L$8<=$C10)+(L$8<=MAX($C10-18,0))+(L$8<=MAX($C10-36,0))-L10)*NOT(ISBLANK($C10)) -> 1 | M11: =SUM(D11:L11) -> 16 | N11: =MAX(0,2+N$7+(N$8<=$C10)+(N$8<=MAX($C10-18,0))+(N$8<=MAX($C10-36,0))-N10)*NOT(ISBLANK($C10)) -> 2 | O11: =MAX(0,2+O$7+(O$8<=$C10)+(O$8<=MAX($C10-18,0))+(O$8<=MAX($C10-36,0))-O10)*NOT(ISBLANK($C10)) -> 1 | P11: =MAX(0,2+P$7+(P$8<=$C10)+(P$8<=MAX($C10-18,0))+(P$8<=MAX($C10-36,0))-P10)*NOT(ISBLANK($C10)) -> 2 | Q11: =MAX(0,2+Q$7+(Q$8<=$C10)+(Q$8<=MAX($C10-18,0))+(Q$8<=MAX($C10-36,0))-Q10)*NOT(ISBLANK($C10)) -> 1 | R11: =MAX(0,2+R$7+(R$8<=$C10)+(R$8<=MAX($C10-18,0))+(R$8<=MAX($C10-36,0))-R10)*NOT(ISBLANK($C10)) -> 1 | S11: =MAX(0,2+S$7+(S$8<=$C10)+(S$8<=MAX($C10-18,0))+(S$8<=MAX($C10-36,0))-S10)*NOT(ISBLANK($C10)) -> 0 | T11: =MAX(0,2+T$7+(T$8<=$C10)+(T$8<=MAX($C10-18,0))+(T$8<=MAX($C10-36,0))-T10)*NOT(ISBLANK($C10)) -> 0 | U11: =MAX(0,2+U$7+(U$8<=$C10)+(U$8<=MAX($C10-18,0))+(U$8<=MAX($C10-36,0))-U10)*NOT(ISBLANK($C10)) -> 3 | V11: =MAX(0,2+V$7+(V$8<=$C10)+(V$8<=MAX($C10-18,0))+(V$8<=MAX($C10-36,0))-V10)*NOT(ISBLANK($C10)) -> 0 | W11: =SUM(N11:V11) -> 10 | X11: =+M11+W11 -> 26 | Z11: {=_xlfn.IFS( AND(Z10 >= 50, Z10 <= 70), 70, AND(Z10 >= 70, Z10 <= 75), 50, AND(Z10 >= 75, Z10 <= 80), 40, AND(Z10 >= 81, Z10 <= 85), 35, AND(Z10 >= 85, Z10 <= 90), 30, AND(Z10 >= 90, Z10 <= 110), 25, AND(Z10 >= 110),0 )} -> 30 | AA11: =SUMIF(D11:L11, ">2")+SUMIF(N11:V11, ">2") -> 12 | AB11: 10 | AC11: 5 | AD11: 5 | AE11: =SUM(Z11:AD11) -> 62 | AG11: 81-85 | AH11: 35
B12: Colby | C12: 20 | D12: 7 | E12: 5 | F12: 5 | G12: 5 | H12: 5 | I12: 4 | J12: 4 | K12: 4 | L12: 7 | M12: =SUM(D12:L12) -> 46 | N12: 8 | O12: 9 | P12: 5 | Q12: 5 | R12: 5 | S12: 2 | T12: 6 | U12: 5 | V12: 6 | W12: =SUM(N12:V12) -> 51 | X12: =+M12+W12 -> 97 | Y12: =X13 -> 33 | Z12: =X12-C12 -> 77 | AF12: 4 | AG12: 86-90 | AH12: 30
B13: pts | D13: =MAX(0,2+D$7+(D$8<=$C12)+(D$8<=MAX($C12-18,0))+(D$8<=MAX($C12-36,0))-D12)*NOT(ISBLANK($C12)) -> 0 | E13: =MAX(0,2+E$7+(E$8<=$C12)+(E$8<=MAX($C12-18,0))+(E$8<=MAX($C12-36,0))-E12)*NOT(ISBLANK($C12)) -> 3 | F13: =MAX(0,2+F$7+(F$8<=$C12)+(F$8<=MAX($C12-18,0))+(F$8<=MAX($C12-36,0))-F12)*NOT(ISBLANK($C12)) -> 2 | G13: =MAX(0,2+G$7+(G$8<=$C12)+(G$8<=MAX($C12-18,0))+(G$8<=MAX($C12-36,0))-G12)*NOT(ISBLANK($C12)) -> 1 | H13: =MAX(0,2+H$7+(H$8<=$C12)+(H$8<=MAX($C12-18,0))+(H$8<=MAX($C12-36,0))-H12)*NOT(ISBLANK($C12)) -> 2 | I13: =MAX(0,2+I$7+(I$8<=$C12)+(I$8<=MAX($C12-18,0))+(I$8<=MAX($C12-36,0))-I12)*NOT(ISBLANK($C12)) -> 3 | J13: =MAX(0,2+J$7+(J$8<=$C12)+(J$8<=MAX($C12-18,0))+(J$8<=MAX($C12-36,0))-J12)*NOT(ISBLANK($C12)) -> 2 | K13: =MAX(0,2+K$7+(K$8<=$C12)+(K$8<=MAX($C12-18,0))+(K$8<=MAX($C12-36,0))-K12)*NOT(ISBLANK($C12)) -> 4 | L13: =MAX(0,2+L$7+(L$8<=$C12)+(L$8<=MAX($C12-18,0))+(L$8<=MAX($C12-36,0))-L12)*NOT(ISBLANK($C12)) -> 1 | M13: =SUM(D13:L13) -> 18 | N13: =MAX(0,2+N$7+(N$8<=$C12)+(N$8<=MAX($C12-18,0))+(N$8<=MAX($C12-36,0))-N12)*NOT(ISBLANK($C12)) -> 0 | O13: =MAX(0,2+O$7+(O$8<=$C12)+(O$8<=MAX($C12-18,0))+(O$8<=MAX($C12-36,0))-O12)*NOT(ISBLANK($C12)) -> 0 | P13: =MAX(0,2+P$7+(P$8<=$C12)+(P$8<=MAX($C12-18,0))+(P$8<=MAX($C12-36,0))-P12)*NOT(ISBLANK($C12)) -> 1 | Q13: =MAX(0,2+Q$7+(Q$8<=$C12)+(Q$8<=MAX($C12-18,0))+(Q$8<=MAX($C12-36,0))-Q12)*NOT(ISBLANK($C12)) -> 2 | R13: =MAX(0,2+R$7+(R$8<=$C12)+(R$8<=MAX($C12-18,0))+(R$8<=MAX($C12-36,0))-R12)*NOT(ISBLANK($C12)) -> 3 | S13: =MAX(0,2+S$7+(S$8<=$C12)+(S$8<=MAX($C12-18,0))+(S$8<=MAX($C12-36,0))-S12)*NOT(ISBLANK($C12)) -> 4 | T13: =MAX(0,2+T$7+(T$8<=$C12)+(T$8<=MAX($C12-18,0))+(T$8<=MAX($C12-36,0))-T12)*NOT(ISBLANK($C12)) -> 1 | U13: =MAX(0,2+U$7+(U$8<=$C12)+(U$8<=MAX($C12-18,0))+(U$8<=MAX($C12-36,0))-U12)*NOT(ISBLANK($C12)) -> 2 | V13: =MAX(0,2+V$7+(V$8<=$C12)+(V$8<=MAX($C12-18,0))+(V$8<=MAX($C12-36,0))-V12)*NOT(ISBLANK($C12)) -> 2 | W13: =SUM(N13:V13) -> 15 | X13: =+M13+W13 -> 33 | Z13: {=_xlfn.IFS( AND(Z12 >= 50, Z12 <= 70), 70, AND(Z12 >= 70, Z12 <= 75), 50, AND(Z12 >= 75, Z12 <= 80), 40, AND(Z12 >= 81, Z12 <= 85), 35, AND(Z12 >= 85, Z12 <= 90), 30, AND(Z12 >= 90, Z12 <= 110), 25, AND(Z12 >= 110),0 )} -> 40 | AA13: =SUMIF(D13:L13, ">2")+SUMIF(N13:V13, ">2") -> 17 | AB13: 0 | AD13: 0 | AE13: =SUM(Z13:AD13) -> 57 | AG13: 91-100+ | AH13: 25
B14: Scott | C14: 25 | D14: 5 | E14: 8 | F14: 8 | G14: 4 | H14: 3 | I14: 6 | J14: 3 | K14: 9 | L14: 5 | M14: =SUM(D14:L14) -> 51 | N14: 5 | O14: 4 | P14: 5 | Q14: 6 | R14: 6 | S14: 5 | T14: 10 | U14: 4 | V14: 8 | W14: =SUM(N14:V14) -> 53 | X14: =+M14+W14 -> 104 | Y14: =X15 -> 32 | Z14: =X14-C14 -> 79 | AF14: 1 | AG14: 3+ points | AH14: equal value
B15: pts | D15: =MAX(0,2+D$7+(D$8<=$C14)+(D$8<=MAX($C14-18,0))+(D$8<=MAX($C14-36,0))-D14)*NOT(ISBLANK($C14)) -> 3 | E15: =MAX(0,2+E$7+(E$8<=$C14)+(E$8<=MAX($C14-18,0))+(E$8<=MAX($C14-36,0))-E14)*NOT(ISBLANK($C14)) -> 0 | F15: =MAX(0,2+F$7+(F$8<=$C14)+(F$8<=MAX($C14-18,0))+(F$8<=MAX($C14-36,0))-F14)*NOT(ISBLANK($C14)) -> 0 | G15: =MAX(0,2+G$7+(G$8<=$C14)+(G$8<=MAX($C14-18,0))+(G$8<=MAX($C14-36,0))-G14)*NOT(ISBLANK($C14)) -> 2 | H15: =MAX(0,2+H$7+(H$8<=$C14)+(H$8<=MAX($C14-18,0))+(H$8<=MAX($C14-36,0))-H14)*NOT(ISBLANK($C14)) -> 4 | I15: =MAX(0,2+I$7+(I$8<=$C14)+(I$8<=MAX($C14-18,0))+(I$8<=MAX($C14-36,0))-I14)*NOT(ISBLANK($C14)) -> 1 | J15: =MAX(0,2+J$7+(J$8<=$C14)+(J$8<=MAX($C14-18,0))+(J$8<=MAX($C14-36,0))-J14)*NOT(ISBLANK($C14)) -> 3 | K15: =MAX(0,2+K$7+(K$8<=$C14)+(K$8<=MAX($C14-18,0))+(K$8<=MAX($C14-36,0))-K14)*NOT(ISBLANK($C14)) -> 0 | L15: =MAX(0,2+L$7+(L$8<=$C14)+(L$8<=MAX($C14-18,0))+(L$8<=MAX($C14-36,0))-L14)*NOT(ISBLANK($C14)) -> 3 | M15: =SUM(D15:L15) -> 16 | N15: =MAX(0,2+N$7+(N$8<=$C14)+(N$8<=MAX($C14-18,0))+(N$8<=MAX($C14-36,0))-N14)*NOT(ISBLANK($C14)) -> 3 | O15: =MAX(0,2+O$7+(O$8<=$C14)+(O$8<=MAX($C14-18,0))+(O$8<=MAX($C14-36,0))-O14)*NOT(ISBLANK($C14)) -> 3 | P15: =MAX(0,2+P$7+(P$8<=$C14)+(P$8<=MAX($C14-18,0))+(P$8<=MAX($C14-36,0))-P14)*NOT(ISBLANK($C14)) -> 1 | Q15: =MAX(0,2+Q$7+(Q$8<=$C14)+(Q$8<=MAX($C14-18,0))+(Q$8<=MAX($C14-36,0))-Q14)*NOT(ISBLANK($C14)) -> 1 | R15: =MAX(0,2+R$7+(R$8<=$C14)+(R$8<=MAX($C14-18,0))+(R$8<=MAX($C14-36,0))-R14)*NOT(ISBLANK($C14)) -> 2 | S15: =MAX(0,2+S$7+(S$8<=$C14)+(S$8<=MAX($C14-18,0))+(S$8<=MAX($C14-36,0))-S14)*NOT(ISBLANK($C14)) -> 1 | T15: =MAX(0,2+T$7+(T$8<=$C14)+(T$8<=MAX($C14-18,0))+(T$8<=MAX($C14-36,0))-T14)*NOT(ISBLANK($C14)) -> 0 | U15: =MAX(0,2+U$7+(U$8<=$C14)+(U$8<=MAX($C14-18,0))+(U$8<=MAX($C14-36,0))-U14)*NOT(ISBLANK($C14)) -> 4 | V15: =MAX(0,2+V$7+(V$8<=$C14)+(V$8<=MAX($C14-18,0))+(V$8<=MAX($C14-36,0))-V14)*NOT(ISBLANK($C14)) -> 1 | W15: =SUM(N15:V15) -> 16 | X15: =+M15+W15 -> 32 | Z15: {=_xlfn.IFS( AND(Z14 >= 50, Z14 <= 70), 70, AND(Z14 >= 70, Z14 <= 75), 50, AND(Z14 >= 75, Z14 <= 80), 40, AND(Z14 >= 81, Z14 <= 85), 35, AND(Z14 >= 85, Z14 <= 90), 30, AND(Z14 >= 90, Z14 <= 110), 25, AND(Z14 >= 110),0 )} -> 40 | AA15: =SUMIF(D15:L15, ">2")+SUMIF(N15:V15, ">2") -> 23 | AB15: 0 | AE15: =SUM(Z15:AD15) -> 63 | AG15: Par 3's | AH15: 5
B16: Dave | C16: 18 | D16: 3 | E16: 9 | F16: 6 | G16: 5 | H16: 4 | I16: 5 | J16: 4 | K16: 5 | L16: 5 | M16: =SUM(D16:L16) -> 46 | N16: 4 | O16: 7 | P16: 4 | Q16: 3 | R16: 5 | S16: 4 | T16: 8 | U16: 5 | V16: 6 | W16: =SUM(N16:V16) -> 46 | X16: =+M16+W16 -> 92 | Y16: =X17 -> 36 | Z16: =X16-C16 -> 74 | AF16: 4 | AG16: Par 5's | AH16: 5
B17: pts | D17: =MAX(0,2+D$7+(D$8<=$C16)+(D$8<=MAX($C16-18,0))+(D$8<=MAX($C16-36,0))-D16)*NOT(ISBLANK($C16)) -> 4 | E17: =MAX(0,2+E$7+(E$8<=$C16)+(E$8<=MAX($C16-18,0))+(E$8<=MAX($C16-36,0))-E16)*NOT(ISBLANK($C16)) -> 0 | F17: =MAX(0,2+F$7+(F$8<=$C16)+(F$8<=MAX($C16-18,0))+(F$8<=MAX($C16-36,0))-F16)*NOT(ISBLANK($C16)) -> 1 | G17: =MAX(0,2+G$7+(G$8<=$C16)+(G$8<=MAX($C16-18,0))+(G$8<=MAX($C16-36,0))-G16)*NOT(ISBLANK($C16)) -> 1 | H17: =MAX(0,2+H$7+(H$8<=$C16)+(H$8<=MAX($C16-18,0))+(H$8<=MAX($C16-36,0))-H16)*NOT(ISBLANK($C16)) -> 3 | I17: =MAX(0,2+I$7+(I$8<=$C16)+(I$8<=MAX($C16-18,0))+(I$8<=MAX($C16-36,0))-I16)*NOT(ISBLANK($C16)) -> 2 | J17: =MAX(0,2+J$7+(J$8<=$C16)+(J$8<=MAX($C16-18,0))+(J$8<=MAX($C16-36,0))-J16)*NOT(ISBLANK($C16)) -> 2 | K17: =MAX(0,2+K$7+(K$8<=$C16)+(K$8<=MAX($C16-18,0))+(K$8<=MAX($C16-36,0))-K16)*NOT(ISBLANK($C16)) -> 3 | L17: =MAX(0,2+L$7+(L$8<=$C16)+(L$8<=MAX($C16-18,0))+(L$8<=MAX($C16-36,0))-L16)*NOT(ISBLANK($C16)) -> 2 | M17: =SUM(D17:L17) -> 18 | N17: =MAX(0,2+N$7+(N$8<=$C16)+(N$8<=MAX($C16-18,0))+(N$8<=MAX($C16-36,0))-N16)*NOT(ISBLANK($C16)) -> 4 | O17: =MAX(0,2+O$7+(O$8<=$C16)+(O$8<=MAX($C16-18,0))+(O$8<=MAX($C16-36,0))-O16)*NOT(ISBLANK($C16)) -> 0 | P17: =MAX(0,2+P$7+(P$8<=$C16)+(P$8<=MAX($C16-18,0))+(P$8<=MAX($C16-36,0))-P16)*NOT(ISBLANK($C16)) -> 2 | Q17: =MAX(0,2+Q$7+(Q$8<=$C16)+(Q$8<=MAX($C16-18,0))+(Q$8<=MAX($C16-36,0))-Q16)*NOT(ISBLANK($C16)) -> 4 | R17: =MAX(0,2+R$7+(R$8<=$C16)+(R$8<=MAX($C16-18,0))+(R$8<=MAX($C16-36,0))-R16)*NOT(ISBLANK($C16)) -> 2 | S17: =MAX(0,2+S$7+(S$8<=$C16)+(S$8<=MAX($C16-18,0))+(S$8<=MAX($C16-36,0))-S16)*NOT(ISBLANK($C16)) -> 2 | T17: =MAX(0,2+T$7+(T$8<=$C16)+(T$8<=MAX($C16-18,0))+(T$8<=MAX($C16-36,0))-T16)*NOT(ISBLANK($C16)) -> 0 | U17: =MAX(0,2+U$7+(U$8<=$C16)+(U$8<=MAX($C16-18,0))+(U$8<=MAX($C16-36,0))-U16)*NOT(ISBLANK($C16)) -> 2 | V17: =MAX(0,2+V$7+(V$8<=$C16)+(V$8<=MAX($C16-18,0))+(V$8<=MAX($C16-36,0))-V16)*NOT(ISBLANK($C16)) -> 2 | W17: =SUM(N17:V17) -> 18 | X17: =+M17+W17 -> 36 | Z17: {=_xlfn.IFS( AND(Z16 >= 50, Z16 <= 70), 70, AND(Z16 >= 70, Z16 <= 75), 50, AND(Z16 >= 75, Z16 <= 80), 40, AND(Z16 >= 81, Z16 <= 85), 35, AND(Z16 >= 85, Z16 <= 90), 30, AND(Z16 >= 90, Z16 <= 110), 25, AND(Z16 >= 110),0 )} -> 50 | AA17: =SUMIF(D17:L17, ">2")+SUMIF(N17:V17, ">2") -> 18 | AB17: 10 | AD17: 0 | AE17: =SUM(Z17:AD17) -> 78 | AG17: Team | AH17: 10
B21: Scratch rating | C21: 73
B22: Slope rating | C22: 135
B23: Par | C23: 72

Sheet Feb - Toronto
C4: Golf Course - Toronto
C5: Date: 8/5/2026
C6: Hole | D6: 1 | E6: 2 | F6: 3 | G6: 4 | H6: 5 | I6: 6 | J6: 7 | K6: 8 | L6: 9 | M6: F/Nine | N6: 10 | O6: 11 | P6: 12 | Q6: 13 | R6: 14 | S6: 15 | T6: 16 | U6: 17 | V6: 18 | W6: B/Nine | X6: Total | Y6: S/Pnts | Z6: Net | AA6: 3+ | AB6: Team | AC6: Par 3 | AD6: Par 5 | AE6: Total | AF6: 3 putts
C7: Par | D7: 4 | E7: 4 | F7: 3 | G7: 4 | H7: 4 | I7: 4 | J7: 4 | K7: 5 | L7: 3 | M7: =SUM(D7:L7) -> 35 | N7: 4 | O7: 5 | P7: 3 | Q7: 4 | R7: 4 | S7: 3 | T7: 4 | U7: 5 | V7: 4 | W7: =SUM(N7:V7) -> 36 | X7: =M7+W7 -> 71 | AA7: Points | AB7: Points | AC7: Points | AD7: Points | AE7: Points | AG7: Net Score | AH7: Points
C8: Index | D8: 8 | E8: 12 | F8: 17 | G8: 10 | H8: 1 | I8: 6 | J8: 4 | K8: 15 | L8: 14 | N8: 11 | O8: 2 | P8: 9 | Q8: 3 | R8: 5 | S8: 13 | T8: 18 | U8: 16 | V8: 7 | AG8: <70 | AH8: 70
C9: H/Cap | AG9: 71-75 | AH9: 50
B10: Mitch | C10: 12 | D10: 8 | E10: 5 | F10: 4 | G10: 6 | H10: 5 | I10: 5 | J10: 5 | K10: 5 | L10: 3 | M10: =SUM(D10:L10) -> 46 | N10: 6 | O10: 6 | P10: 4 | Q10: 6 | R10: 5 | S10: 4 | T10: 5 | U10: 6 | V10: 5 | W10: =SUM(N10:V10) -> 47 | X10: =+M10+W10 -> 93 | Y10: =X11 -> 27 | Z10: =X10-C10 -> 81 | AF10: 4 | AG10: 76-80 | AH10: 40
B11: pts | D11: =MAX(0,2+D$7+(D$8<=$C10)+(D$8<=MAX($C10-18,0))+(D$8<=MAX($C10-36,0))-D10)*NOT(ISBLANK($C10)) -> 0 | E11: =MAX(0,2+E$7+(E$8<=$C10)+(E$8<=MAX($C10-18,0))+(E$8<=MAX($C10-36,0))-E10)*NOT(ISBLANK($C10)) -> 2 | F11: =MAX(0,2+F$7+(F$8<=$C10)+(F$8<=MAX($C10-18,0))+(F$8<=MAX($C10-36,0))-F10)*NOT(ISBLANK($C10)) -> 1 | G11: =MAX(0,2+G$7+(G$8<=$C10)+(G$8<=MAX($C10-18,0))+(G$8<=MAX($C10-36,0))-G10)*NOT(ISBLANK($C10)) -> 1 | H11: =MAX(0,2+H$7+(H$8<=$C10)+(H$8<=MAX($C10-18,0))+(H$8<=MAX($C10-36,0))-H10)*NOT(ISBLANK($C10)) -> 2 | I11: =MAX(0,2+I$7+(I$8<=$C10)+(I$8<=MAX($C10-18,0))+(I$8<=MAX($C10-36,0))-I10)*NOT(ISBLANK($C10)) -> 2 | J11: =MAX(0,2+J$7+(J$8<=$C10)+(J$8<=MAX($C10-18,0))+(J$8<=MAX($C10-36,0))-J10)*NOT(ISBLANK($C10)) -> 2 | K11: =MAX(0,2+K$7+(K$8<=$C10)+(K$8<=MAX($C10-18,0))+(K$8<=MAX($C10-36,0))-K10)*NOT(ISBLANK($C10)) -> 2 | L11: =MAX(0,2+L$7+(L$8<=$C10)+(L$8<=MAX($C10-18,0))+(L$8<=MAX($C10-36,0))-L10)*NOT(ISBLANK($C10)) -> 2 | M11: =SUM(D11:L11) -> 14 | N11: =MAX(0,2+N$7+(N$8<=$C10)+(N$8<=MAX($C10-18,0))+(N$8<=MAX($C10-36,0))-N10)*NOT(ISBLANK($C10)) -> 1 | O11: =MAX(0,2+O$7+(O$8<=$C10)+(O$8<=MAX($C10-18,0))+(O$8<=MAX($C10-36,0))-O10)*NOT(ISBLANK($C10)) -> 2 | P11: =MAX(0,2+P$7+(P$8<=$C10)+(P$8<=MAX($C10-18,0))+(P$8<=MAX($C10-36,0))-P10)*NOT(ISBLANK($C10)) -> 2 | Q11: =MAX(0,2+Q$7+(Q$8<=$C10)+(Q$8<=MAX($C10-18,0))+(Q$8<=MAX($C10-36,0))-Q10)*NOT(ISBLANK($C10)) -> 1 | R11: =MAX(0,2+R$7+(R$8<=$C10)+(R$8<=MAX($C10-18,0))+(R$8<=MAX($C10-36,0))-R10)*NOT(ISBLANK($C10)) -> 2 | S11: =MAX(0,2+S$7+(S$8<=$C10)+(S$8<=MAX($C10-18,0))+(S$8<=MAX($C10-36,0))-S10)*NOT(ISBLANK($C10)) -> 1 | T11: =MAX(0,2+T$7+(T$8<=$C10)+(T$8<=MAX($C10-18,0))+(T$8<=MAX($C10-36,0))-T10)*NOT(ISBLANK($C10)) -> 1 | U11: =MAX(0,2+U$7+(U$8<=$C10)+(U$8<=MAX($C10-18,0))+(U$8<=MAX($C10-36,0))-U10)*NOT(ISBLANK($C10)) -> 1 | V11: =MAX(0,2+V$7+(V$8<=$C10)+(V$8<=MAX($C10-18,0))+(V$8<=MAX($C10-36,0))-V10)*NOT(ISBLANK($C10)) -> 2 | W11: =SUM(N11:V11) -> 13 | X11: =+M11+W11 -> 27 | Z11: {=_xlfn.IFS( AND(Z10 >= 50, Z10 <= 70), 70, AND(Z10 >= 70, Z10 <= 75), 50, AND(Z10 >= 75, Z10 <= 80), 40, AND(Z10 >= 81, Z10 <= 85), 35, AND(Z10 >= 85, Z10 <= 90), 30, AND(Z10 >= 90, Z10 <= 110), 25, AND(Z10 >= 110),0 )} -> 35 | AA11: =SUMIF(D11:L11, ">2")+SUMIF(N11:V11, ">2") -> 0 | AB11: 10 | AC11: 0 | AD11: 0 | AE11: =SUM(Z11:AD11) -> 45 | AG11: 81-85 | AH11: 35
B12: Colby | C12: 16 | D12: 5 | E12: 5 | F12: 3 | G12: 5 | H12: 4 | I12: 5 | J12: 5 | K12: 6 | L12: 5 | M12: =SUM(D12:L12) -> 43 | N12: 4 | O12: 6 | P12: 4 | Q12: 7 | R12: 5 | S12: 4 | T12: 5 | U12: 6 | V12: 6 | W12: =SUM(N12:V12) -> 47 | X12: =+M12+W12 -> 90 | Y12: =X13 -> 33 | Z12: =X12-C12 -> 74 | AF12: 2 | AG12: 86-90 | AH12: 30
B13: pts | D13: =MAX(0,2+D$7+(D$8<=$C12)+(D$8<=MAX($C12-18,0))+(D$8<=MAX($C12-36,0))-D12)*NOT(ISBLANK($C12)) -> 2 | E13: =MAX(0,2+E$7+(E$8<=$C12)+(E$8<=MAX($C12-18,0))+(E$8<=MAX($C12-36,0))-E12)*NOT(ISBLANK($C12)) -> 2 | F13: =MAX(0,2+F$7+(F$8<=$C12)+(F$8<=MAX($C12-18,0))+(F$8<=MAX($C12-36,0))-F12)*NOT(ISBLANK($C12)) -> 2 | G13: =MAX(0,2+G$7+(G$8<=$C12)+(G$8<=MAX($C12-18,0))+(G$8<=MAX($C12-36,0))-G12)*NOT(ISBLANK($C12)) -> 2 | H13: =MAX(0,2+H$7+(H$8<=$C12)+(H$8<=MAX($C12-18,0))+(H$8<=MAX($C12-36,0))-H12)*NOT(ISBLANK($C12)) -> 3 | I13: =MAX(0,2+I$7+(I$8<=$C12)+(I$8<=MAX($C12-18,0))+(I$8<=MAX($C12-36,0))-I12)*NOT(ISBLANK($C12)) -> 2 | J13: =MAX(0,2+J$7+(J$8<=$C12)+(J$8<=MAX($C12-18,0))+(J$8<=MAX($C12-36,0))-J12)*NOT(ISBLANK($C12)) -> 2 | K13: =MAX(0,2+K$7+(K$8<=$C12)+(K$8<=MAX($C12-18,0))+(K$8<=MAX($C12-36,0))-K12)*NOT(ISBLANK($C12)) -> 2 | L13: =MAX(0,2+L$7+(L$8<=$C12)+(L$8<=MAX($C12-18,0))+(L$8<=MAX($C12-36,0))-L12)*NOT(ISBLANK($C12)) -> 1 | M13: =SUM(D13:L13) -> 18 | N13: =MAX(0,2+N$7+(N$8<=$C12)+(N$8<=MAX($C12-18,0))+(N$8<=MAX($C12-36,0))-N12)*NOT(ISBLANK($C12)) -> 3 | O13: =MAX(0,2+O$7+(O$8<=$C12)+(O$8<=MAX($C12-18,0))+(O$8<=MAX($C12-36,0))-O12)*NOT(ISBLANK($C12)) -> 2 | P13: =MAX(0,2+P$7+(P$8<=$C12)+(P$8<=MAX($C12-18,0))+(P$8<=MAX($C12-36,0))-P12)*NOT(ISBLANK($C12)) -> 2 | Q13: =MAX(0,2+Q$7+(Q$8<=$C12)+(Q$8<=MAX($C12-18,0))+(Q$8<=MAX($C12-36,0))-Q12)*NOT(ISBLANK($C12)) -> 0 | R13: =MAX(0,2+R$7+(R$8<=$C12)+(R$8<=MAX($C12-18,0))+(R$8<=MAX($C12-36,0))-R12)*NOT(ISBLANK($C12)) -> 2 | S13: =MAX(0,2+S$7+(S$8<=$C12)+(S$8<=MAX($C12-18,0))+(S$8<=MAX($C12-36,0))-S12)*NOT(ISBLANK($C12)) -> 2 | T13: =MAX(0,2+T$7+(T$8<=$C12)+(T$8<=MAX($C12-18,0))+(T$8<=MAX($C12-36,0))-T12)*NOT(ISBLANK($C12)) -> 1 | U13: =MAX(0,2+U$7+(U$8<=$C12)+(U$8<=MAX($C12-18,0))+(U$8<=MAX($C12-36,0))-U12)*NOT(ISBLANK($C12)) -> 2 | V13: =MAX(0,2+V$7+(V$8<=$C12)+(V$8<=MAX($C12-18,0))+(V$8<=MAX($C12-36,0))-V12)*NOT(ISBLANK($C12)) -> 1 | W13: =SUM(N13:V13) -> 15 | X13: =+M13+W13 -> 33 | Z13: {=_xlfn.IFS( AND(Z12 >= 50, Z12 <= 70), 70, AND(Z12 >= 70, Z12 <= 75), 50, AND(Z12 >= 75, Z12 <= 80), 40, AND(Z12 >= 81, Z12 <= 85), 35, AND(Z12 >= 85, Z12 <= 90), 30, AND(Z12 >= 90, Z12 <= 110), 25, AND(Z12 >= 110),0 )} -> 50 | AA13: =SUMIF(D13:L13, ">2")+SUMIF(N13:V13, ">2") -> 6 | AB13: 10 | AC13: 5 | AD13: 5 | AE13: =SUM(Z13:AD13) -> 76 | AG13: 91-100+ | AH13: 25
B14: Scott | C14: 21 | D14: 6 | E14: 6 | F14: 4 | G14: 8 | H14: 5 | I14: 5 | J14: 6 | K14: 8 | L14: 4 | M14: =SUM(D14:L14) -> 52 | N14: 4 | O14: 7 | P14: 3 | Q14: 6 | R14: 5 | S14: 3 | T14: 7 | U14: 5 | V14: 6 | W14: =SUM(N14:V14) -> 46 | X14: =+M14+W14 -> 98 | Y14: =X15 -> 31 | Z14: =X14-C14 -> 77 | AF14: 0 | AG14: 3+ points | AH14: equal value
B15: pts | D15: =MAX(0,2+D$7+(D$8<=$C14)+(D$8<=MAX($C14-18,0))+(D$8<=MAX($C14-36,0))-D14)*NOT(ISBLANK($C14)) -> 1 | E15: =MAX(0,2+E$7+(E$8<=$C14)+(E$8<=MAX($C14-18,0))+(E$8<=MAX($C14-36,0))-E14)*NOT(ISBLANK($C14)) -> 1 | F15: =MAX(0,2+F$7+(F$8<=$C14)+(F$8<=MAX($C14-18,0))+(F$8<=MAX($C14-36,0))-F14)*NOT(ISBLANK($C14)) -> 2 | G15: =MAX(0,2+G$7+(G$8<=$C14)+(G$8<=MAX($C14-18,0))+(G$8<=MAX($C14-36,0))-G14)*NOT(ISBLANK($C14)) -> 0 | H15: =MAX(0,2+H$7+(H$8<=$C14)+(H$8<=MAX($C14-18,0))+(H$8<=MAX($C14-36,0))-H14)*NOT(ISBLANK($C14)) -> 3 | I15: =MAX(0,2+I$7+(I$8<=$C14)+(I$8<=MAX($C14-18,0))+(I$8<=MAX($C14-36,0))-I14)*NOT(ISBLANK($C14)) -> 2 | J15: =MAX(0,2+J$7+(J$8<=$C14)+(J$8<=MAX($C14-18,0))+(J$8<=MAX($C14-36,0))-J14)*NOT(ISBLANK($C14)) -> 1 | K15: =MAX(0,2+K$7+(K$8<=$C14)+(K$8<=MAX($C14-18,0))+(K$8<=MAX($C14-36,0))-K14)*NOT(ISBLANK($C14)) -> 0 | L15: =MAX(0,2+L$7+(L$8<=$C14)+(L$8<=MAX($C14-18,0))+(L$8<=MAX($C14-36,0))-L14)*NOT(ISBLANK($C14)) -> 2 | M15: =SUM(D15:L15) -> 12 | N15: =MAX(0,2+N$7+(N$8<=$C14)+(N$8<=MAX($C14-18,0))+(N$8<=MAX($C14-36,0))-N14)*NOT(ISBLANK($C14)) -> 3 | O15: =MAX(0,2+O$7+(O$8<=$C14)+(O$8<=MAX($C14-18,0))+(O$8<=MAX($C14-36,0))-O14)*NOT(ISBLANK($C14)) -> 2 | P15: =MAX(0,2+P$7+(P$8<=$C14)+(P$8<=MAX($C14-18,0))+(P$8<=MAX($C14-36,0))-P14)*NOT(ISBLANK($C14)) -> 3 | Q15: =MAX(0,2+Q$7+(Q$8<=$C14)+(Q$8<=MAX($C14-18,0))+(Q$8<=MAX($C14-36,0))-Q14)*NOT(ISBLANK($C14)) -> 2 | R15: =MAX(0,2+R$7+(R$8<=$C14)+(R$8<=MAX($C14-18,0))+(R$8<=MAX($C14-36,0))-R14)*NOT(ISBLANK($C14)) -> 2 | S15: =MAX(0,2+S$7+(S$8<=$C14)+(S$8<=MAX($C14-18,0))+(S$8<=MAX($C14-36,0))-S14)*NOT(ISBLANK($C14)) -> 3 | T15: =MAX(0,2+T$7+(T$8<=$C14)+(T$8<=MAX($C14-18,0))+(T$8<=MAX($C14-36,0))-T14)*NOT(ISBLANK($C14)) -> 0 | U15: =MAX(0,2+U$7+(U$8<=$C14)+(U$8<=MAX($C14-18,0))+(U$8<=MAX($C14-36,0))-U14)*NOT(ISBLANK($C14)) -> 3 | V15: =MAX(0,2+V$7+(V$8<=$C14)+(V$8<=MAX($C14-18,0))+(V$8<=MAX($C14-36,0))-V14)*NOT(ISBLANK($C14)) -> 1 | W15: =SUM(N15:V15) -> 19 | X15: =+M15+W15 -> 31 | Z15: {=_xlfn.IFS( AND(Z14 >= 50, Z14 <= 70), 70, AND(Z14 >= 70, Z14 <= 75), 50, AND(Z14 >= 75, Z14 <= 80), 40, AND(Z14 >= 81, Z14 <= 85), 35, AND(Z14 >= 85, Z14 <= 90), 30, AND(Z14 >= 90, Z14 <= 110), 25, AND(Z14 >= 110),0 )} -> 40 | AA15: =SUMIF(D15:L15, ">2")+SUMIF(N15:V15, ">2") -> 15 | AB15: 0 | AC15: 0 | AD15: 0 | AE15: =SUM(Z15:AD15) -> 55 | AG15: Par 3's | AH15: 5
B16: Dave | C16: 14 | D16: 4 | E16: 4 | F16: 5 | G16: 6 | H16: 5 | I16: 5 | J16: 4 | K16: 7 | L16: 4 | M16: =SUM(D16:L16) -> 44 | N16: 4 | O16: 7 | P16: 4 | Q16: 4 | R16: 5 | S16: 5 | T16: 5 | U16: 6 | V16: 7 | W16: =SUM(N16:V16) -> 47 | X16: =+M16+W16 -> 91 | Y16: =X17 -> 30 | Z16: =X16-C16 -> 77 | AF16: 4 | AG16: Par 5's | AH16: 5
B17: pts | D17: =MAX(0,2+D$7+(D$8<=$C16)+(D$8<=MAX($C16-18,0))+(D$8<=MAX($C16-36,0))-D16)*NOT(ISBLANK($C16)) -> 3 | E17: =MAX(0,2+E$7+(E$8<=$C16)+(E$8<=MAX($C16-18,0))+(E$8<=MAX($C16-36,0))-E16)*NOT(ISBLANK($C16)) -> 3 | F17: =MAX(0,2+F$7+(F$8<=$C16)+(F$8<=MAX($C16-18,0))+(F$8<=MAX($C16-36,0))-F16)*NOT(ISBLANK($C16)) -> 0 | G17: =MAX(0,2+G$7+(G$8<=$C16)+(G$8<=MAX($C16-18,0))+(G$8<=MAX($C16-36,0))-G16)*NOT(ISBLANK($C16)) -> 1 | H17: =MAX(0,2+H$7+(H$8<=$C16)+(H$8<=MAX($C16-18,0))+(H$8<=MAX($C16-36,0))-H16)*NOT(ISBLANK($C16)) -> 2 | I17: =MAX(0,2+I$7+(I$8<=$C16)+(I$8<=MAX($C16-18,0))+(I$8<=MAX($C16-36,0))-I16)*NOT(ISBLANK($C16)) -> 2 | J17: =MAX(0,2+J$7+(J$8<=$C16)+(J$8<=MAX($C16-18,0))+(J$8<=MAX($C16-36,0))-J16)*NOT(ISBLANK($C16)) -> 3 | K17: =MAX(0,2+K$7+(K$8<=$C16)+(K$8<=MAX($C16-18,0))+(K$8<=MAX($C16-36,0))-K16)*NOT(ISBLANK($C16)) -> 0 | L17: =MAX(0,2+L$7+(L$8<=$C16)+(L$8<=MAX($C16-18,0))+(L$8<=MAX($C16-36,0))-L16)*NOT(ISBLANK($C16)) -> 2 | M17: =SUM(D17:L17) -> 16 | N17: =MAX(0,2+N$7+(N$8<=$C16)+(N$8<=MAX($C16-18,0))+(N$8<=MAX($C16-36,0))-N16)*NOT(ISBLANK($C16)) -> 3 | O17: =MAX(0,2+O$7+(O$8<=$C16)+(O$8<=MAX($C16-18,0))+(O$8<=MAX($C16-36,0))-O16)*NOT(ISBLANK($C16)) -> 1 | P17: =MAX(0,2+P$7+(P$8<=$C16)+(P$8<=MAX($C16-18,0))+(P$8<=MAX($C16-36,0))-P16)*NOT(ISBLANK($C16)) -> 2 | Q17: =MAX(0,2+Q$7+(Q$8<=$C16)+(Q$8<=MAX($C16-18,0))+(Q$8<=MAX($C16-36,0))-Q16)*NOT(ISBLANK($C16)) -> 3 | R17: =MAX(0,2+R$7+(R$8<=$C16)+(R$8<=MAX($C16-18,0))+(R$8<=MAX($C16-36,0))-R16)*NOT(ISBLANK($C16)) -> 2 | S17: =MAX(0,2+S$7+(S$8<=$C16)+(S$8<=MAX($C16-18,0))+(S$8<=MAX($C16-36,0))-S16)*NOT(ISBLANK($C16)) -> 1 | T17: =MAX(0,2+T$7+(T$8<=$C16)+(T$8<=MAX($C16-18,0))+(T$8<=MAX($C16-36,0))-T16)*NOT(ISBLANK($C16)) -> 1 | U17: =MAX(0,2+U$7+(U$8<=$C16)+(U$8<=MAX($C16-18,0))+(U$8<=MAX($C16-36,0))-U16)*NOT(ISBLANK($C16)) -> 1 | V17: =MAX(0,2+V$7+(V$8<=$C16)+(V$8<=MAX($C16-18,0))+(V$8<=MAX($C16-36,0))-V16)*NOT(ISBLANK($C16)) -> 0 | W17: =SUM(N17:V17) -> 14 | X17: =+M17+W17 -> 30 | Z17: {=_xlfn.IFS( AND(Z16 >= 50, Z16 <= 70), 70, AND(Z16 >= 70, Z16 <= 75), 50, AND(Z16 >= 75, Z16 <= 80), 40, AND(Z16 >= 81, Z16 <= 85), 35, AND(Z16 >= 85, Z16 <= 90), 30, AND(Z16 >= 90, Z16 <= 110), 25, AND(Z16 >= 110),0 )} -> 40 | AA17: =SUMIF(D17:L17, ">2")+SUMIF(N17:V17, ">2") -> 15 | AB17: 0 | AC17: 0 | AD17: 0 | AE17: =SUM(Z17:AD17) -> 55 | AG17: Team | AH17: 10
B21: Scratch rating | C21: 73
B22: Slope rating | C22: 135
B23: Par | C23: 72

Sheet Mar - Shortland
C4: Golf Course - Shortland
C5: Date: 1/6/2026
C6: Hole | D6: 1 | E6: 2 | F6: 3 | G6: 4 | H6: 5 | I6: 6 | J6: 7 | K6: 8 | L6: 9 | M6: F/Nine | N6: 10 | O6: 11 | P6: 12 | Q6: 13 | R6: 14 | S6: 15 | T6: 16 | U6: 17 | V6: 18 | W6: B/Nine | X6: Total | Y6: S/Pnts | Z6: Net | AA6: 3+ | AB6: Team | AC6: Par 3 | AD6: Par 5 | AE6: Total | AF6: 3 putts
C7: Par | D7: 5 | E7: 3 | F7: 4 | G7: 3 | H7: 5 | I7: 4 | J7: 4 | K7: 5 | L7: 4 | M7: =SUM(D7:L7) -> 37 | N7: 4 | O7: 3 | P7: 4 | Q7: 5 | R7: 3 | S7: 4 | T7: 4 | U7: 3 | V7: 4 | W7: =SUM(N7:V7) -> 34 | X7: =M7+W7 -> 71 | AA7: Points | AB7: Points | AC7: Points | AD7: Points | AE7: Points | AG7: Net Score | AH7: Points
C8: Index | D8: 10 | E8: 8 | F8: 14 | G8: 4 | H8: 11 | I8: 15 | J8: 9 | K8: 17 | L8: 1 | N8: 16 | O8: 12 | P8: 5 | Q8: 7 | R8: 18 | S8: 3 | T8: 2 | U8: 6 | V8: 13 | AG8: <70 | AH8: 70
C9: H/Cap | AG9: 71-75 | AH9: 50
B10: Mitch | C10: 14 | D10: 6 | E10: 5 | F10: 6 | G10: 3 | H10: 6 | I10: 4 | J10: 5 | K10: 8 | L10: 5 | M10: =SUM(D10:L10) -> 48 | N10: 6 | O10: 7 | P10: 4 | Q10: 7 | R10: 4 | S10: 6 | T10: 5 | U10: 4 | V10: 5 | W10: =SUM(N10:V10) -> 48 | X10: =+M10+W10 -> 96 | Y10: =X11 -> 27 | Z10: =X10-C10 -> 82 | AF10: 1 | AG10: 76-80 | AH10: 40
B11: pts | D11: =MAX(0,2+D$7+(D$8<=$C10)+(D$8<=MAX($C10-18,0))+(D$8<=MAX($C10-36,0))-D10)*NOT(ISBLANK($C10)) -> 2 | E11: =MAX(0,2+E$7+(E$8<=$C10)+(E$8<=MAX($C10-18,0))+(E$8<=MAX($C10-36,0))-E10)*NOT(ISBLANK($C10)) -> 1 | F11: =MAX(0,2+F$7+(F$8<=$C10)+(F$8<=MAX($C10-18,0))+(F$8<=MAX($C10-36,0))-F10)*NOT(ISBLANK($C10)) -> 1 | G11: =MAX(0,2+G$7+(G$8<=$C10)+(G$8<=MAX($C10-18,0))+(G$8<=MAX($C10-36,0))-G10)*NOT(ISBLANK($C10)) -> 3 | H11: =MAX(0,2+H$7+(H$8<=$C10)+(H$8<=MAX($C10-18,0))+(H$8<=MAX($C10-36,0))-H10)*NOT(ISBLANK($C10)) -> 2 | I11: =MAX(0,2+I$7+(I$8<=$C10)+(I$8<=MAX($C10-18,0))+(I$8<=MAX($C10-36,0))-I10)*NOT(ISBLANK($C10)) -> 2 | J11: =MAX(0,2+J$7+(J$8<=$C10)+(J$8<=MAX($C10-18,0))+(J$8<=MAX($C10-36,0))-J10)*NOT(ISBLANK($C10)) -> 2 | K11: =MAX(0,2+K$7+(K$8<=$C10)+(K$8<=MAX($C10-18,0))+(K$8<=MAX($C10-36,0))-K10)*NOT(ISBLANK($C10)) -> 0 | L11: =MAX(0,2+L$7+(L$8<=$C10)+(L$8<=MAX($C10-18,0))+(L$8<=MAX($C10-36,0))-L10)*NOT(ISBLANK($C10)) -> 2 | M11: =SUM(D11:L11) -> 15 | N11: =MAX(0,2+N$7+(N$8<=$C10)+(N$8<=MAX($C10-18,0))+(N$8<=MAX($C10-36,0))-N10)*NOT(ISBLANK($C10)) -> 0 | O11: =MAX(0,2+O$7+(O$8<=$C10)+(O$8<=MAX($C10-18,0))+(O$8<=MAX($C10-36,0))-O10)*NOT(ISBLANK($C10)) -> 0 | P11: =MAX(0,2+P$7+(P$8<=$C10)+(P$8<=MAX($C10-18,0))+(P$8<=MAX($C10-36,0))-P10)*NOT(ISBLANK($C10)) -> 3 | Q11: =MAX(0,2+Q$7+(Q$8<=$C10)+(Q$8<=MAX($C10-18,0))+(Q$8<=MAX($C10-36,0))-Q10)*NOT(ISBLANK($C10)) -> 1 | R11: =MAX(0,2+R$7+(R$8<=$C10)+(R$8<=MAX($C10-18,0))+(R$8<=MAX($C10-36,0))-R10)*NOT(ISBLANK($C10)) -> 1 | S11: =MAX(0,2+S$7+(S$8<=$C10)+(S$8<=MAX($C10-18,0))+(S$8<=MAX($C10-36,0))-S10)*NOT(ISBLANK($C10)) -> 1 | T11: =MAX(0,2+T$7+(T$8<=$C10)+(T$8<=MAX($C10-18,0))+(T$8<=MAX($C10-36,0))-T10)*NOT(ISBLANK($C10)) -> 2 | U11: =MAX(0,2+U$7+(U$8<=$C10)+(U$8<=MAX($C10-18,0))+(U$8<=MAX($C10-36,0))-U10)*NOT(ISBLANK($C10)) -> 2 | V11: =MAX(0,2+V$7+(V$8<=$C10)+(V$8<=MAX($C10-18,0))+(V$8<=MAX($C10-36,0))-V10)*NOT(ISBLANK($C10)) -> 2 | W11: =SUM(N11:V11) -> 12 | X11: =+M11+W11 -> 27 | Z11: {=_xlfn.IFS( AND(Z10 >= 50, Z10 <= 70), 70, AND(Z10 >= 70, Z10 <= 75), 50, AND(Z10 >= 75, Z10 <= 80), 40, AND(Z10 >= 81, Z10 <= 85), 35, AND(Z10 >= 85, Z10 <= 90), 30, AND(Z10 >= 90, Z10 <= 110), 25, AND(Z10 >= 110),0 )} -> 35 | AA11: =SUMIF(D11:L11, ">2")+SUMIF(N11:V11, ">2") -> 6 | AB11: 10 | AC11: 0 | AD11: 0 | AE11: =SUM(Z11:AD11) -> 51 | AG11: 81-85 | AH11: 35
B12: Colby | C12: 18 | D12: 7 | E12: 4 | F12: 5 | G12: 4 | H12: 7 | I12: 6 | J12: 5 | K12: 5 | L12: 6 | M12: =SUM(D12:L12) -> 49 | N12: 5 | O12: 3 | P12: 5 | Q12: 5 | R12: 3 | S12: 7 | T12: 6 | U12: 4 | V12: 5 | W12: =SUM(N12:V12) -> 43 | X12: =+M12+W12 -> 92 | Y12: =X13 -> 33 | Z12: =X12-C12 -> 74 | AF12: 2 | AG12: 86-90 | AH12: 30
B13: pts | D13: =MAX(0,2+D$7+(D$8<=$C12)+(D$8<=MAX($C12-18,0))+(D$8<=MAX($C12-36,0))-D12)*NOT(ISBLANK($C12)) -> 1 | E13: =MAX(0,2+E$7+(E$8<=$C12)+(E$8<=MAX($C12-18,0))+(E$8<=MAX($C12-36,0))-E12)*NOT(ISBLANK($C12)) -> 2 | F13: =MAX(0,2+F$7+(F$8<=$C12)+(F$8<=MAX($C12-18,0))+(F$8<=MAX($C12-36,0))-F12)*NOT(ISBLANK($C12)) -> 2 | G13: =MAX(0,2+G$7+(G$8<=$C12)+(G$8<=MAX($C12-18,0))+(G$8<=MAX($C12-36,0))-G12)*NOT(ISBLANK($C12)) -> 2 | H13: =MAX(0,2+H$7+(H$8<=$C12)+(H$8<=MAX($C12-18,0))+(H$8<=MAX($C12-36,0))-H12)*NOT(ISBLANK($C12)) -> 1 | I13: =MAX(0,2+I$7+(I$8<=$C12)+(I$8<=MAX($C12-18,0))+(I$8<=MAX($C12-36,0))-I12)*NOT(ISBLANK($C12)) -> 1 | J13: =MAX(0,2+J$7+(J$8<=$C12)+(J$8<=MAX($C12-18,0))+(J$8<=MAX($C12-36,0))-J12)*NOT(ISBLANK($C12)) -> 2 | K13: =MAX(0,2+K$7+(K$8<=$C12)+(K$8<=MAX($C12-18,0))+(K$8<=MAX($C12-36,0))-K12)*NOT(ISBLANK($C12)) -> 3 | L13: =MAX(0,2+L$7+(L$8<=$C12)+(L$8<=MAX($C12-18,0))+(L$8<=MAX($C12-36,0))-L12)*NOT(ISBLANK($C12)) -> 1 | M13: =SUM(D13:L13) -> 15 | N13: =MAX(0,2+N$7+(N$8<=$C12)+(N$8<=MAX($C12-18,0))+(N$8<=MAX($C12-36,0))-N12)*NOT(ISBLANK($C12)) -> 2 | O13: =MAX(0,2+O$7+(O$8<=$C12)+(O$8<=MAX($C12-18,0))+(O$8<=MAX($C12-36,0))-O12)*NOT(ISBLANK($C12)) -> 3 | P13: =MAX(0,2+P$7+(P$8<=$C12)+(P$8<=MAX($C12-18,0))+(P$8<=MAX($C12-36,0))-P12)*NOT(ISBLANK($C12)) -> 2 | Q13: =MAX(0,2+Q$7+(Q$8<=$C12)+(Q$8<=MAX($C12-18,0))+(Q$8<=MAX($C12-36,0))-Q12)*NOT(ISBLANK($C12)) -> 3 | R13: =MAX(0,2+R$7+(R$8<=$C12)+(R$8<=MAX($C12-18,0))+(R$8<=MAX($C12-36,0))-R12)*NOT(ISBLANK($C12)) -> 3 | S13: =MAX(0,2+S$7+(S$8<=$C12)+(S$8<=MAX($C12-18,0))+(S$8<=MAX($C12-36,0))-S12)*NOT(ISBLANK($C12)) -> 0 | T13: =MAX(0,2+T$7+(T$8<=$C12)+(T$8<=MAX($C12-18,0))+(T$8<=MAX($C12-36,0))-T12)*NOT(ISBLANK($C12)) -> 1 | U13: =MAX(0,2+U$7+(U$8<=$C12)+(U$8<=MAX($C12-18,0))+(U$8<=MAX($C12-36,0))-U12)*NOT(ISBLANK($C12)) -> 2 | V13: =MAX(0,2+V$7+(V$8<=$C12)+(V$8<=MAX($C12-18,0))+(V$8<=MAX($C12-36,0))-V12)*NOT(ISBLANK($C12)) -> 2 | W13: =SUM(N13:V13) -> 18 | X13: =+M13+W13 -> 33 | Z13: {=_xlfn.IFS( AND(Z12 >= 50, Z12 <= 70), 70, AND(Z12 >= 70, Z12 <= 75), 50, AND(Z12 >= 75, Z12 <= 80), 40, AND(Z12 >= 81, Z12 <= 85), 35, AND(Z12 >= 85, Z12 <= 90), 30, AND(Z12 >= 90, Z12 <= 110), 25, AND(Z12 >= 110),0 )} -> 50 | AA13: =SUMIF(D13:L13, ">2")+SUMIF(N13:V13, ">2") -> 12 | AB13: 10 | AC13: 0 | AD13: 5 | AE13: =SUM(Z13:AD13) -> 77 | AG13: 91-100+ | AH13: 25
B14: Scott | C14: 23 | D14: 7 | E14: 5 | F14: 5 | G14: 5 | H14: 8 | I14: 6 | J14: 6 | K14: 6 | L14: 7 | M14: =SUM(D14:L14) -> 55 | N14: 6 | O14: 5 | P14: 6 | Q14: 10 | R14: 3 | S14: 7 | T14: 8 | U14: 3 | V14: 7 | W14: =SUM(N14:V14) -> 55 | X14: =+M14+W14 -> 110 | Y14: =X15 -> 22 | Z14: =X14-C14 -> 87 | AF14: 4 | AG14: 3+ points | AH14: equal value
B15: pts | D15: =MAX(0,2+D$7+(D$8<=$C14)+(D$8<=MAX($C14-18,0))+(D$8<=MAX($C14-36,0))-D14)*NOT(ISBLANK($C14)) -> 1 | E15: =MAX(0,2+E$7+(E$8<=$C14)+(E$8<=MAX($C14-18,0))+(E$8<=MAX($C14-36,0))-E14)*NOT(ISBLANK($C14)) -> 1 | F15: =MAX(0,2+F$7+(F$8<=$C14)+(F$8<=MAX($C14-18,0))+(F$8<=MAX($C14-36,0))-F14)*NOT(ISBLANK($C14)) -> 2 | G15: =MAX(0,2+G$7+(G$8<=$C14)+(G$8<=MAX($C14-18,0))+(G$8<=MAX($C14-36,0))-G14)*NOT(ISBLANK($C14)) -> 2 | H15: =MAX(0,2+H$7+(H$8<=$C14)+(H$8<=MAX($C14-18,0))+(H$8<=MAX($C14-36,0))-H14)*NOT(ISBLANK($C14)) -> 0 | I15: =MAX(0,2+I$7+(I$8<=$C14)+(I$8<=MAX($C14-18,0))+(I$8<=MAX($C14-36,0))-I14)*NOT(ISBLANK($C14)) -> 1 | J15: =MAX(0,2+J$7+(J$8<=$C14)+(J$8<=MAX($C14-18,0))+(J$8<=MAX($C14-36,0))-J14)*NOT(ISBLANK($C14)) -> 1 | K15: =MAX(0,2+K$7+(K$8<=$C14)+(K$8<=MAX($C14-18,0))+(K$8<=MAX($C14-36,0))-K14)*NOT(ISBLANK($C14)) -> 2 | L15: =MAX(0,2+L$7+(L$8<=$C14)+(L$8<=MAX($C14-18,0))+(L$8<=MAX($C14-36,0))-L14)*NOT(ISBLANK($C14)) -> 1 | M15: =SUM(D15:L15) -> 11 | N15: =MAX(0,2+N$7+(N$8<=$C14)+(N$8<=MAX($C14-18,0))+(N$8<=MAX($C14-36,0))-N14)*NOT(ISBLANK($C14)) -> 1 | O15: =MAX(0,2+O$7+(O$8<=$C14)+(O$8<=MAX($C14-18,0))+(O$8<=MAX($C14-36,0))-O14)*NOT(ISBLANK($C14)) -> 1 | P15: =MAX(0,2+P$7+(P$8<=$C14)+(P$8<=MAX($C14-18,0))+(P$8<=MAX($C14-36,0))-P14)*NOT(ISBLANK($C14)) -> 2 | Q15: =MAX(0,2+Q$7+(Q$8<=$C14)+(Q$8<=MAX($C14-18,0))+(Q$8<=MAX($C14-36,0))-Q14)*NOT(ISBLANK($C14)) -> 0 | R15: =MAX(0,2+R$7+(R$8<=$C14)+(R$8<=MAX($C14-18,0))+(R$8<=MAX($C14-36,0))-R14)*NOT(ISBLANK($C14)) -> 3 | S15: =MAX(0,2+S$7+(S$8<=$C14)+(S$8<=MAX($C14-18,0))+(S$8<=MAX($C14-36,0))-S14)*NOT(ISBLANK($C14)) -> 1 | T15: =MAX(0,2+T$7+(T$8<=$C14)+(T$8<=MAX($C14-18,0))+(T$8<=MAX($C14-36,0))-T14)*NOT(ISBLANK($C14)) -> 0 | U15: =MAX(0,2+U$7+(U$8<=$C14)+(U$8<=MAX($C14-18,0))+(U$8<=MAX($C14-36,0))-U14)*NOT(ISBLANK($C14)) -> 3 | V15: =MAX(0,2+V$7+(V$8<=$C14)+(V$8<=MAX($C14-18,0))+(V$8<=MAX($C14-36,0))-V14)*NOT(ISBLANK($C14)) -> 0 | W15: =SUM(N15:V15) -> 11 | X15: =+M15+W15 -> 22 | Z15: {=_xlfn.IFS( AND(Z14 >= 50, Z14 <= 70), 70, AND(Z14 >= 70, Z14 <= 75), 50, AND(Z14 >= 75, Z14 <= 80), 40, AND(Z14 >= 81, Z14 <= 85), 35, AND(Z14 >= 85, Z14 <= 90), 30, AND(Z14 >= 90, Z14 <= 110), 25, AND(Z14 >= 110),0 )} -> 30 | AA15: =SUMIF(D15:L15, ">2")+SUMIF(N15:V15, ">2") -> 6 | AB15: 0 | AC15: 0 | AD15: 0 | AE15: =SUM(Z15:AD15) -> 36 | AG15: Par 3's | AH15: 5
B16: Dave | C16: 16 | D16: 8 | E16: 4 | F16: 6 | G16: 4 | H16: 7 | I16: 5 | J16: 7 | K16: 7 | L16: 7 | M16: =SUM(D16:L16) -> 55 | N16: 6 | O16: 4 | P16: 7 | Q16: 6 | R16: 3 | S16: 5 | T16: 6 | U16: 5 | V16: 6 | W16: =SUM(N16:V16) -> 48 | X16: =+M16+W16 -> 103 | Y16: =X17 -> 20 | Z16: =X16-C16 -> 87 | AF16: 4 | AG16: Par 5's | AH16: 5
B17: pts | D17: =MAX(0,2+D$7+(D$8<=$C16)+(D$8<=MAX($C16-18,0))+(D$8<=MAX($C16-36,0))-D16)*NOT(ISBLANK($C16)) -> 0 | E17: =MAX(0,2+E$7+(E$8<=$C16)+(E$8<=MAX($C16-18,0))+(E$8<=MAX($C16-36,0))-E16)*NOT(ISBLANK($C16)) -> 2 | F17: =MAX(0,2+F$7+(F$8<=$C16)+(F$8<=MAX($C16-18,0))+(F$8<=MAX($C16-36,0))-F16)*NOT(ISBLANK($C16)) -> 1 | G17: =MAX(0,2+G$7+(G$8<=$C16)+(G$8<=MAX($C16-18,0))+(G$8<=MAX($C16-36,0))-G16)*NOT(ISBLANK($C16)) -> 2 | H17: =MAX(0,2+H$7+(H$8<=$C16)+(H$8<=MAX($C16-18,0))+(H$8<=MAX($C16-36,0))-H16)*NOT(ISBLANK($C16)) -> 1 | I17: =MAX(0,2+I$7+(I$8<=$C16)+(I$8<=MAX($C16-18,0))+(I$8<=MAX($C16-36,0))-I16)*NOT(ISBLANK($C16)) -> 2 | J17: =MAX(0,2+J$7+(J$8<=$C16)+(J$8<=MAX($C16-18,0))+(J$8<=MAX($C16-36,0))-J16)*NOT(ISBLANK($C16)) -> 0 | K17: =MAX(0,2+K$7+(K$8<=$C16)+(K$8<=MAX($C16-18,0))+(K$8<=MAX($C16-36,0))-K16)*NOT(ISBLANK($C16)) -> 0 | L17: =MAX(0,2+L$7+(L$8<=$C16)+(L$8<=MAX($C16-18,0))+(L$8<=MAX($C16-36,0))-L16)*NOT(ISBLANK($C16)) -> 0 | M17: =SUM(D17:L17) -> 8 | N17: =MAX(0,2+N$7+(N$8<=$C16)+(N$8<=MAX($C16-18,0))+(N$8<=MAX($C16-36,0))-N16)*NOT(ISBLANK($C16)) -> 1 | O17: =MAX(0,2+O$7+(O$8<=$C16)+(O$8<=MAX($C16-18,0))+(O$8<=MAX($C16-36,0))-O16)*NOT(ISBLANK($C16)) -> 2 | P17: =MAX(0,2+P$7+(P$8<=$C16)+(P$8<=MAX($C16-18,0))+(P$8<=MAX($C16-36,0))-P16)*NOT(ISBLANK($C16)) -> 0 | Q17: =MAX(0,2+Q$7+(Q$8<=$C16)+(Q$8<=MAX($C16-18,0))+(Q$8<=MAX($C16-36,0))-Q16)*NOT(ISBLANK($C16)) -> 2 | R17: =MAX(0,2+R$7+(R$8<=$C16)+(R$8<=MAX($C16-18,0))+(R$8<=MAX($C16-36,0))-R16)*NOT(ISBLANK($C16)) -> 2 | S17: =MAX(0,2+S$7+(S$8<=$C16)+(S$8<=MAX($C16-18,0))+(S$8<=MAX($C16-36,0))-S16)*NOT(ISBLANK($C16)) -> 2 | T17: =MAX(0,2+T$7+(T$8<=$C16)+(T$8<=MAX($C16-18,0))+(T$8<=MAX($C16-36,0))-T16)*NOT(ISBLANK($C16)) -> 1 | U17: =MAX(0,2+U$7+(U$8<=$C16)+(U$8<=MAX($C16-18,0))+(U$8<=MAX($C16-36,0))-U16)*NOT(ISBLANK($C16)) -> 1 | V17: =MAX(0,2+V$7+(V$8<=$C16)+(V$8<=MAX($C16-18,0))+(V$8<=MAX($C16-36,0))-V16)*NOT(ISBLANK($C16)) -> 1 | W17: =SUM(N17:V17) -> 12 | X17: =+M17+W17 -> 20 | Z17: {=_xlfn.IFS( AND(Z16 >= 50, Z16 <= 70), 70, AND(Z16 >= 70, Z16 <= 75), 50, AND(Z16 >= 75, Z16 <= 80), 40, AND(Z16 >= 81, Z16 <= 85), 35, AND(Z16 >= 85, Z16 <= 90), 30, AND(Z16 >= 90, Z16 <= 110), 25, AND(Z16 >= 110),0 )} -> 30 | AA17: =SUMIF(D17:L17, ">2")+SUMIF(N17:V17, ">2") -> 0 | AB17: 0 | AC17: 0 | AD17: 0 | AE17: =SUM(Z17:AD17) -> 30 | AG17: Team | AH17: 10
B21: Scratch rating | C21: 72
B22: Slope rating | C22: 128
B23: Par | C23: 72
AM27: Mitch | AN27: Colby | AO27: Scott | AP27: Dave
AK28: March | AL28: Toukley | AM28: 13.194 | AN28: 16.84 | AO28: 21.513 | AP28: 15.072
AM29: 14 | AN29: 18 | AO29: 23 | AP29: 16
AK32: GA | AL32: DAILY | AN32: GA | AO32: DAILY
AK33: HANDICAP | AL33: HANDICAP | AN33: HANDICAP | AO33: HANDICAP
AK34: 1.5 to 2.3 | AL34: 2 | AN34: 12.9 to 13.7 | AO34: 14 (mitch)
AK35: 2.4 to 3.3 | AL35: 3 | AN35: 13.8 to 14.7 | AO35: 15
AK36: 3.4 to 4.2 | AL36: 4 | AN36: 14.8 to 15.6 | AO36: 16 (Dave)
AK37: 4.3 to 5.2 | AL37: 5 | AN37: 15.7 to 16.6 | AO37: 17
AK38: 5.3 to 6.1 | AL38: 6 | AN38: 16.7 to 17.5 | AO38: 18 (Colby)
AK39: 6.2 to 7.1 | AL39: 7 | AN39: 17.6 to 18.5 | AO39: 19
AK40: 7.2 to 8.0 | AL40: 8 | AN40: 18.6 to 19.4 | AO40: 20
AK41: 8.1 to 9.0 | AL41: 9 | AN41: 19.5 to 20.4 | AO41: 21
AK42: 9.1 to 9.9 | AL42: 10 | AN42: 20.5 to 21.3 | AO42: 22
AK43: 10.0 to 10.9 | AL43: 11 | AN43: 21.4 to 22.3 | AO43: 23 (Scott)
AK44: 11.0 to 11.8 | AL44: 12 | AN44: 22.4 to 23.2 | AO44: 24
AK45: 11.9 to 12.8 | AL45: 13 | AN45: 23.3 to 54.0 | AO45: 25

Sheet Apr - Waratah
C4: Golf Course - Waratah
C5: Date: 19/6/2026
C6: Hole | D6: 1 | E6: 2 | F6: 3 | G6: 4 | H6: 5 | I6: 6 | J6: 7 | K6: 8 | L6: 9 | M6: F/Nine | N6: 10 | O6: 11 | P6: 12 | Q6: 13 | R6: 14 | S6: 15 | T6: 16 | U6: 17 | V6: 18 | W6: B/Nine | X6: Total | Y6: S/Pnts | Z6: Net | AA6: 3+ | AB6: Team | AC6: Par 3 | AD6: Par 5 | AE6: Total | AF6: 3 putts
C7: Par | D7: 4 | E7: 5 | F7: 4 | G7: 3 | H7: 4 | I7: 4 | J7: 3 | K7: 5 | L7: 4 | M7: =SUM(D7:L7) -> 36 | N7: 5 | O7: 4 | P7: 3 | Q7: 4 | R7: 4 | S7: 3 | T7: 4 | U7: 4 | V7: 5 | W7: =SUM(N7:V7) -> 36 | X7: =M7+W7 -> 72 | AA7: Points | AB7: Points | AC7: Points | AD7: Points | AE7: Points | AG7: Net Score | AH7: Points
C8: Index | D8: 5 | E8: 9 | F8: 3 | G8: 14 | H8: 11 | I8: 15 | J8: 18 | K8: 13 | L8: 1 | N8: 12 | O8: 10 | P8: 16 | Q8: 8 | R8: 2 | S8: 17 | T8: 6 | U8: 7 | V8: 4 | AG8: <70 | AH8: 70
C9: H/Cap | AG9: 71-75 | AH9: 50
B10: Mitch | C10: 13 | D10: 10 | E10: 10 | F10: 10 | G10: 10 | H10: 10 | I10: 10 | J10: 10 | K10: 10 | L10: 10 | M10: =SUM(D10:L10) -> 90 | N10: 10 | O10: 10 | P10: 10 | Q10: 10 | R10: 10 | S10: 10 | T10: 10 | U10: 10 | V10: 10 | W10: =SUM(N10:V10) -> 90 | X10: =+M10+W10 -> 180 | Y10: =X11 -> 0 | Z10: =X10-C10 -> 167 | AF10: 0 | AG10: 76-80 | AH10: 40
B11: pts | D11: =MAX(0,2+D$7+(D$8<=$C10)+(D$8<=MAX($C10-18,0))+(D$8<=MAX($C10-36,0))-D10)*NOT(ISBLANK($C10)) -> 0 | E11: =MAX(0,2+E$7+(E$8<=$C10)+(E$8<=MAX($C10-18,0))+(E$8<=MAX($C10-36,0))-E10)*NOT(ISBLANK($C10)) -> 0 | F11: =MAX(0,2+F$7+(F$8<=$C10)+(F$8<=MAX($C10-18,0))+(F$8<=MAX($C10-36,0))-F10)*NOT(ISBLANK($C10)) -> 0 | G11: =MAX(0,2+G$7+(G$8<=$C10)+(G$8<=MAX($C10-18,0))+(G$8<=MAX($C10-36,0))-G10)*NOT(ISBLANK($C10)) -> 0 | H11: =MAX(0,2+H$7+(H$8<=$C10)+(H$8<=MAX($C10-18,0))+(H$8<=MAX($C10-36,0))-H10)*NOT(ISBLANK($C10)) -> 0 | I11: =MAX(0,2+I$7+(I$8<=$C10)+(I$8<=MAX($C10-18,0))+(I$8<=MAX($C10-36,0))-I10)*NOT(ISBLANK($C10)) -> 0 | J11: =MAX(0,2+J$7+(J$8<=$C10)+(J$8<=MAX($C10-18,0))+(J$8<=MAX($C10-36,0))-J10)*NOT(ISBLANK($C10)) -> 0 | K11: =MAX(0,2+K$7+(K$8<=$C10)+(K$8<=MAX($C10-18,0))+(K$8<=MAX($C10-36,0))-K10)*NOT(ISBLANK($C10)) -> 0 | L11: =MAX(0,2+L$7+(L$8<=$C10)+(L$8<=MAX($C10-18,0))+(L$8<=MAX($C10-36,0))-L10)*NOT(ISBLANK($C10)) -> 0 | M11: =SUM(D11:L11) -> 0 | N11: =MAX(0,2+N$7+(N$8<=$C10)+(N$8<=MAX($C10-18,0))+(N$8<=MAX($C10-36,0))-N10)*NOT(ISBLANK($C10)) -> 0 | O11: =MAX(0,2+O$7+(O$8<=$C10)+(O$8<=MAX($C10-18,0))+(O$8<=MAX($C10-36,0))-O10)*NOT(ISBLANK($C10)) -> 0 | P11: =MAX(0,2+P$7+(P$8<=$C10)+(P$8<=MAX($C10-18,0))+(P$8<=MAX($C10-36,0))-P10)*NOT(ISBLANK($C10)) -> 0 | Q11: =MAX(0,2+Q$7+(Q$8<=$C10)+(Q$8<=MAX($C10-18,0))+(Q$8<=MAX($C10-36,0))-Q10)*NOT(ISBLANK($C10)) -> 0 | R11: =MAX(0,2+R$7+(R$8<=$C10)+(R$8<=MAX($C10-18,0))+(R$8<=MAX($C10-36,0))-R10)*NOT(ISBLANK($C10)) -> 0 | S11: =MAX(0,2+S$7+(S$8<=$C10)+(S$8<=MAX($C10-18,0))+(S$8<=MAX($C10-36,0))-S10)*NOT(ISBLANK($C10)) -> 0 | T11: =MAX(0,2+T$7+(T$8<=$C10)+(T$8<=MAX($C10-18,0))+(T$8<=MAX($C10-36,0))-T10)*NOT(ISBLANK($C10)) -> 0 | U11: =MAX(0,2+U$7+(U$8<=$C10)+(U$8<=MAX($C10-18,0))+(U$8<=MAX($C10-36,0))-U10)*NOT(ISBLANK($C10)) -> 0 | V11: =MAX(0,2+V$7+(V$8<=$C10)+(V$8<=MAX($C10-18,0))+(V$8<=MAX($C10-36,0))-V10)*NOT(ISBLANK($C10)) -> 0 | W11: =SUM(N11:V11) -> 0 | X11: =+M11+W11 -> 0 | Z11: {=_xlfn.IFS( AND(Z10 >= 50, Z10 <= 70), 70, AND(Z10 >= 70, Z10 <= 75), 50, AND(Z10 >= 75, Z10 <= 80), 40, AND(Z10 >= 81, Z10 <= 85), 35, AND(Z10 >= 85, Z10 <= 90), 30, AND(Z10 >= 90, Z10 <= 110), 25, AND(Z10 >= 110),0 )} -> 0 | AA11: =SUMIF(D11:L11, ">2")+SUMIF(N11:V11, ">2") -> 0 | AB11: 0 | AC11: 0 | AD11: 0 | AE11: =SUM(Z11:AD11) -> 0 | AG11: 81-85 | AH11: 35
B12: Colby | C12: 17 | D12: 10 | E12: 10 | F12: 10 | G12: 10 | H12: 10 | I12: 10 | J12: 10 | K12: 10 | L12: 10 | M12: =SUM(D12:L12) -> 90 | N12: 10 | O12: 10 | P12: 10 | Q12: 10 | R12: 10 | S12: 10 | T12: 10 | U12: 10 | V12: 10 | W12: =SUM(N12:V12) -> 90 | X12: =+M12+W12 -> 180 | Y12: =X13 -> 0 | Z12: =X12-C12 -> 163 | AF12: 0 | AG12: 86-90 | AH12: 30
